<?xml version="1.0"?>
<!--
  Copyright 2016 Pavel Vechersky, ASL, ETH Zurich, Switzerland

  Licensed under the Apache License, Version 2.0 (the "License");
  you may not use this file except in compliance with the License.
  You may obtain a copy of the License at

  http://www.apache.org/licenses/LICENSE-2.0

  Unless required by applicable law or agreed to in writing, software
  distributed under the License is distributed on an "AS IS" BASIS,
  WITHOUT WARRANTIES OR CONDITIONS OF ANY KIND, either express or implied.
  See the License for the specific language governing permissions and
  limitations under the License.
-->

<robot xmlns:xacro="http://ros.org/wiki/xacro">
  <!-- Macro for the inertia of a box -->
  <xacro:macro name="box_inertia" params="x y z mass">
    <inertia ixx="${0.0833333 * mass * (y*y + z*z)}" ixy="0.0" ixz="0.0"
      iyy="${0.0833333 * mass * (x*x + z*z)}" iyz="0.0"
      izz="${0.0833333 * mass * (x*x + y*y)}" />
  </xacro:macro>

  <!-- Macro for the inertia of a cylinder -->
  <xacro:macro name="cylinder_inertia" params="r h mass">
    <inertia ixx="${0.0833333 * mass * (3*r*r + h*h)}" ixy="0.0" ixz="0.0"
      iyy="${0.0833333 * mass * (3*r*r + h*h)}" iyz="0.0"
      izz="${0.5 * mass * r * r}" />
  </xacro:macro>

  <!-- Macro for the inertia of a sphere -->
  <xacro:macro name="sphere_inertia" params="r mass">
    <inertia ixx="${0.4 * mass * r*r}" ixy="0.0" ixz="0.0"
           iyy="${0.4 * mass * r*r}" iyz="0.0"
           izz="${0.4 * mass * r*r}" />
  </xacro:macro>

  <!-- Fixed-wing main body link -->
  <xacro:macro name="fixed_wing_base_macro"
    params="robot_namespace mass length width height color use_mesh_file mesh_file *origin *inertia">
    <link name="${robot_namespace}/base_link">
        <inertial>
          <mass value="${mass}" />
          <xacro:insert_block name="origin" />
          <xacro:insert_block name="inertia" />
        </inertial>
        <visual>
          <origin xyz="0 0 0" rpy="0 0 0" />
          <geometry>
            <xacro:if value="${use_mesh_file}">
              <mesh filename="${mesh_file}" scale="1 1 1" />
            </xacro:if>
            <xacro:unless value="${use_mesh_file}">
              <box size="${length} ${width} ${height}" />
            </xacro:unless>
          </geometry>
        </visual>
        <collision>
          <origin xyz="-0.2 0 0.15" rpy="0 0 0" />
          <geometry>
            <box size="${length} ${width} ${height}" />
          </geometry>
        </collision>
    </link>

    <gazebo reference="${robot_namespace}/base_link">
      <material>Gazebo/${color}</material>
    </gazebo>
  </xacro:macro>

  <!-- Airfoil segment joint, link and plugin -->
  <xacro:macro name="airfoil_segment"
    params="robot_namespace segment_name parent mass_segment do_flex k c color use_mesh_file mesh_file segment_length segment_width
      segment_height *axis *joint_origin *inertia_origin *vis_coll_origin *inertia ">

    <xacro:if value="${do_flex}">
      <joint name="${robot_namespace}/${segment_name}_joint" type="revolute">
        <xacro:insert_block name="joint_origin" />
        <xacro:insert_block name="axis" />
        <parent link="${parent}" />
        <child link="${robot_namespace}/${segment_name}"/>
        <limit upper="0.17" lower="-0.17" effort="5000" velocity="50"/>
        <dynamics damping="${c}"/>
      </joint>
      <gazebo reference="${robot_namespace}/${segment_name}_joint">
        <implicitSpringDamper>true</implicitSpringDamper>
        <springStiffness>${k}</springStiffness>
      </gazebo>
    </xacro:if>
    <xacro:unless value="${do_flex}">
      <joint name="${robot_namespace}/${segment_name}_joint" type="revolute">
        <xacro:insert_block name="joint_origin" />
        <xacro:insert_block name="axis" />
        <parent link="${parent}" />
        <child link="${robot_namespace}/${segment_name}"/>
        <limit upper="0" lower="-0" effort="5000" velocity="50"/>
      </joint>
    </xacro:unless>

    <link name="${robot_namespace}/${segment_name}">
      <inertial>
        <xacro:insert_block name="inertia_origin" />
        <mass value="${mass_segment}" />
        <xacro:box_inertia x="${segment_length}" y="${segment_width}" z="${segment_height}" mass="${mass_segment}" />
      </inertial>
      <visual>
        <xacro:insert_block name="vis_coll_origin" />
        <geometry>
          <xacro:if value="${use_mesh_file}">
            <mesh filename="${mesh_file}" scale="1 1 1" />
          </xacro:if>
          <xacro:unless value="${use_mesh_file}">
            <box size="${segment_length} ${segment_width} ${segment_height}" />
          </xacro:unless>
        </geometry>
      </visual>
      <collision>
        <xacro:insert_block name="vis_coll_origin" />
        <geometry>
          <xacro:if value="${use_mesh_file}">
            <mesh filename="${mesh_file}" scale="1 1 1" />
          </xacro:if>
          <xacro:unless value="${use_mesh_file}">
            <box size="${segment_length} ${segment_width} ${segment_height}" />
          </xacro:unless>
        </geometry>
      </collision>
    </link>

    <gazebo reference="${robot_namespace}/${segment_name}">
      <material>Gazebo/${color}</material>
    </gazebo>

  </xacro:macro>

  <!-- Control surface joint and link -->
  <xacro:macro name="control_surface"
    params="robot_namespace surface_name parent mass_surface min_angle
      max_angle color use_mesh_file mesh_file surface_length surface_width
      surface_height *axis *joint_origin *inertia_origin *vis_coll_origin *inertia">
    <joint name="${robot_namespace}/${surface_name}_joint" type="revolute">
      <xacro:insert_block name="joint_origin" />
      <xacro:insert_block name="axis" />
      <parent link="${parent}" />
      <child link="${robot_namespace}/${surface_name}" />
      <limit upper="${max_angle}" lower="${min_angle}" effort="10" velocity="20"/>
    </joint>

    <link name="${robot_namespace}/${surface_name}">
      <inertial>
        <xacro:insert_block name="inertia_origin" />
        <mass value="${mass_surface}" />
        <xacro:insert_block name="inertia" />
      </inertial>
      <visual>
        <xacro:insert_block name="vis_coll_origin" />
        <geometry>
          <xacro:if value="${use_mesh_file}">
            <mesh filename="${mesh_file}" scale="1 1 1" />
          </xacro:if>
          <xacro:unless value="${use_mesh_file}">
            <box size="${surface_length} ${surface_width} ${surface_height}" />
          </xacro:unless>
        </geometry>
      </visual>
      <!--
      <collision>
        <xacro:insert_block name="vis_coll_origin" />
        <geometry>
          <xacro:if value="${use_mesh_file}">
            <mesh filename="${mesh_file}" scale="1 1 1" />
          </xacro:if>
          <xacro:unless value="${use_mesh_file}">
            <box size="${surface_length} ${surface_width} ${surface_height}" />
          </xacro:unless>
        </geometry>
      </collision>
      -->
    </link>

    <gazebo reference="${robot_namespace}/${surface_name}">
      <material>Gazebo/${color}</material>
    </gazebo>
  </xacro:macro>

  <!-- Propeller joint and link -->
  <xacro:macro name="propeller"
    params="robot_namespace suffix parent mass_propeller propeller_radius color
      use_mesh_file mesh_file *origin *vis_coll_origin *inertia">
    <joint name="${robot_namespace}/propeller_${suffix}_joint" type="continuous">
      <xacro:insert_block name="origin" />
      <axis xyz="0 0 1" />
      <parent link="${parent}" />
      <child link="${robot_namespace}/propeller_${suffix}" />
    </joint>

    <link name="${robot_namespace}/propeller_${suffix}">
      <inertial>
        <mass value="${mass_propeller}" />
        <xacro:insert_block name="inertia" />
      </inertial>
      <visual>
        <xacro:insert_block name="vis_coll_origin" />
        <geometry>
          <xacro:if value="${use_mesh_file}">
            <mesh filename="${mesh_file}"/>
          </xacro:if>
          <xacro:unless value="${use_mesh_file}">
            <cylinder length="0.005" radius="${propeller_radius}"/>
          </xacro:unless>
        </geometry>
      </visual>
      <!--
      <collision>
        <xacro:insert_block name="vis_coll_origin" />
        <geometry>
          <xacro:if value="${use_mesh_file}">
            <mesh filename="${mesh_file}"/>
          </xacro:if>
          <xacro:unless value="${use_mesh_file}">
            <cylinder length="0.005" radius="${propeller_radius}"/>
          </xacro:unless>
        </geometry>
      </collision>
      -->
    </link>

    <gazebo reference="${robot_namespace}/propeller_${suffix}">
      <material>Gazebo/${color}</material>
    </gazebo>
  </xacro:macro>

  <!-- Aerodyn. angle vane -->
  <xacro:macro name="angle_vane"
    params="robot_namespace vane_name type chord arm_cp parent wind_topic mass_vane
            color *joint_origin *inertia">

    <joint name="${robot_namespace}/${vane_name}_joint" type="continuous">
      <xacro:insert_block name="joint_origin" />
      <xacro:if value="${type=='alpha'}">
         <axis xyz="0 1 0" />
       </xacro:if>
       <xacro:if value="${type=='beta'}">
         <axis xyz="0 0 -1" />
       </xacro:if>
       <parent link="${parent}" />
       <child link="${robot_namespace}/${vane_name}" />
       <dynamics friction="0" damping="0.00001"/>
    </joint>

    <link name="${robot_namespace}/${vane_name}">
      <inertial>
        <mass value="${mass_vane}" />
        <xacro:insert_block name="inertia" />
      </inertial>
      <visual>
        <geometry>
          <box size="0.1 0.003 0.003" />
        </geometry>
      </visual>
      <visual>
        <xacro:if value="${type=='alpha'}">
          <origin xyz="-0.04 0.02 0" rpy="0 0 0" />
          <geometry>
            <box size="0.02 0.04 0.002" />
          </geometry>
        </xacro:if>
        <xacro:if value="${type=='beta'}">
          <origin xyz="-0.04 0 0.02" rpy="0 0 0" />
          <geometry>
            <box size="0.02 0.002 0.04" />
          </geometry>
        </xacro:if>
      </visual>
    </link>

    <gazebo reference="${robot_namespace}/${vane_name}">
      <material>Gazebo/${color}</material>
    </gazebo>

    <xacro:if value="${type=='alpha'}">
     <gazebo>
       <plugin filename="librotors_gazebo_aerodynamics_plugin.so" name="aerodynamics_plugin">
         <robotNamespace>${namespace}</robotNamespace>
         <linkName>${robot_namespace}/${vane_name}</linkName>
          <aeroForcesVis>aero_force_vis_${vane_name}</aeroForcesVis>
          <airfoil>
            <segment name="alpha_vane">
              <forward>1 0 0</forward>
              <upward>0 0 1</upward>
              <cp>${-arm_cp} 0 0</cp>
              <seg_area>${2*chord*chord}</seg_area>
              <seg_chord>${chord}</seg_chord>
              <aeroParamsYAML>${yaml_path}/airfoil_test_2.yaml</aeroParamsYAML>
              <wind name="wind">
                <topic>${wind_topic}</topic>
              </wind>
            </segment>
          </airfoil>
        </plugin>
      </gazebo>
    </xacro:if>

    <xacro:if value="${type=='beta'}">
     <gazebo>
       <plugin filename="librotors_gazebo_aerodynamics_plugin.so" name="aerodynamics_plugin">
         <robotNamespace>${namespace}</robotNamespace>
         <linkName>${robot_namespace}/${vane_name}</linkName>
          <aeroForcesVis>aero_force_vis_${vane_name}</aeroForcesVis>
          <airfoil>
            <segment name="beta_vane">
              <forward>1 0 0</forward>
              <upward>0 -1 0</upward>
              <cp>${-arm_cp} 0 0</cp>
              <seg_area>${2*chord*chord}</seg_area>
              <seg_chord>${chord}</seg_chord>
              <aeroParamsYAML>${yaml_path}/airfoil_test_2.yaml</aeroParamsYAML>
              <wind name="wind">
                <topic>${wind_topic}</topic>
              </wind>
            </segment>
          </airfoil>
        </plugin>
      </gazebo>
    </xacro:if>

  </xacro:macro>

</robot>
