<?xml version="1.0"?>
<!--
  Copyright 2015 Fadri Furrer, ASL, ETH Zurich, Switzerland
  Copyright 2015 Michael Burri, ASL, ETH Zurich, Switzerland
  Copyright 2015 Mina Kamel, ASL, ETH Zurich, Switzerland
  Copyright 2015 Janosch Nikolic, ASL, ETH Zurich, Switzerland
  Copyright 2015 Markus Achtelik, ASL, ETH Zurich, Switzerland

  Licensed under the Apache License, Version 2.0 (the "License");
  you may not use this file except in compliance with the License.
  You may obtain a copy of the License at

  http://www.apache.org/licenses/LICENSE-2.0

  Unless required by applicable law or agreed to in writing, software
  distributed under the License is distributed on an "AS IS" BASIS,
  WITHOUT WARRANTIES OR CONDITIONS OF ANY KIND, either express or implied.
  See the License for the specific language governing permissions and
  limitations under the License.
-->

<robot xmlns:xacro="http://ros.org/wiki/xacro">

  <xacro:include filename="$(find rotors_description)/urdf/multirotor_base.xacro"/>

  <xacro:macro name="omav_base_macro"
    params="robot_namespace mass body_width body_height use_mesh_file mesh_file use_collision_mesh_file collision_mesh_file *origin *inertia *inertia_origin">
    <link name="${robot_namespace}/base_link"></link>

    <joint name="${robot_namespace}/base_joint" type="fixed">
      <xacro:insert_block name="origin" />
      <parent link="${robot_namespace}/base_link" />
      <child link="${robot_namespace}/base_link_inertia" />
    </joint>

    <link name="${robot_namespace}/base_link_inertia">
      <inertial>
        <mass value="${mass}" />  <!-- [kg] -->
        <xacro:insert_block name="inertia_origin" />
        <xacro:insert_block name="inertia" />
      </inertial>

      <visual>
        <origin xyz="0 0 0" rpy="0 0 0" />
        <geometry>
          <xacro:if value="${use_mesh_file}">
            <mesh filename="${mesh_file}" scale="1 1 1" />
          </xacro:if>
          <xacro:unless value="${use_mesh_file}">
            <box size="${body_width} ${body_width} ${body_height}"/> <!-- [m] [m] [m] -->
          </xacro:unless>
        </geometry>
      </visual>

      <collision>
        <origin xyz="0 0 0" rpy="0 0 0" />
        <geometry>
          <xacro:if value="${use_collision_mesh_file}">
            <mesh filename="${collision_mesh_file}" scale="1 1 1" />
          </xacro:if>
          <xacro:unless value="${use_collision_mesh_file}">
            <box size="${body_width} ${body_width} ${body_height}"/> <!-- [m] [m] [m] -->
          </xacro:unless>
        </geometry>
      </collision>

      <surface>
        <friction>
          <ode>
            <mu>0.5</mu>
            <mu2>0.5</mu2>
          </ode>
        </friction>
        <bounce>
          <restitution_coefficient>0.01</restitution_coefficient>
          <threshold>0.01</threshold>
        </bounce>
        <contact>
          <ode>
            <max_vel>0.1</max_vel>
            <soft_cfm>0.8</soft_cfm>
            <soft_erp>0.8</soft_erp>
            <kd>2500</kd>
            <kp>10</kp>
            <min_depth>0.001</min_depth>
          </ode>
        </contact>
      </surface>
    </link>

    <!-- attach multirotor_base_plugin to the base_link -->
    <gazebo>
      <plugin filename="librotors_gazebo_multirotor_base_plugin.so" name="multirotor_base_plugin">
        <robotNamespace>${robot_namespace}</robotNamespace>
        <linkName>${robot_namespace}/base_link</linkName>
        <rotorVelocitySlowdownSim>${rotor_velocity_slowdown_sim}</rotorVelocitySlowdownSim>
      </plugin>
    </gazebo>
  </xacro:macro>

  <!-- Tilting rotor unit link and joint. -->
  <xacro:macro name="single_tilt_unit_minimal"
    params="robot_namespace direction parent mass_rotor mass_tilt_unit rotor_offset_top motor_number color mesh mesh_tilt_unit *origin *inertia">

    <!-- Rotor tilt_unit -->
    <joint name="${robot_namespace}/tilt_unit_${motor_number}_revolutejoint" type="continuous">
      <xacro:insert_block name="origin" />
      <axis xyz="1 0 0" />
      <dynamics damping="0.035" friction="0" />
      <parent link="${parent}" />
      <child link="${namespace}/tilt_unit_${motor_number}" />
    </joint>

    <gazebo reference="${robot_namespace}/tilt_unit_${motor_number}_revolutejoint">
      <provideFeedback>true</provideFeedback>
    </gazebo>

    <link name="${namespace}/tilt_unit_${motor_number}">
      <inertial>
        <mass value="${mass_tilt_unit}" /> <!-- [kg] -->
        <xacro:insert_block name="tilt_unit_inertia" />
      </inertial>
      <visual>
        <geometry>
            <mesh filename="${mesh_tilt_unit}"
              scale="1 1 1" />
        </geometry>
      </visual>
      <collision>
        <geometry>
          <box size="0.005 0.005 0.005"  /> <!-- [m] -->
        </geometry>
      </collision>
    </link>

    <gazebo reference="${namespace}/tilt_unit_${motor_number}">
      <material>Gazebo/White</material>
    </gazebo>

    <!-- Rotor -->
    <joint name="rotor_${motor_number}_joint" type="continuous">
      <origin xyz="0 0 ${rotor_offset_top}" rpy="0 0 0" />
      <axis xyz="0 0 1" />
      <parent link="${namespace}/tilt_unit_${motor_number}" />
      <child link="rotor_${motor_number}" />
    </joint>

    <link name="rotor_${motor_number}">
      <inertial>
        <mass value="${mass_rotor}" /> <!-- [kg] -->
        <xacro:insert_block name="inertia" />
      </inertial>
      <visual>
        <geometry>
          <mesh filename="package://rotors_description/meshes/${mesh}_${direction}.dae"
            scale="${radius_rotor} ${radius_rotor} ${radius_rotor}" />
        </geometry>
      </visual>
      <collision>
        <geometry>
          <cylinder length="0.005" radius="${radius_rotor}" /> <!-- [m] -->
        </geometry>
      </collision>
    </link>

    <gazebo reference="rotor_${motor_number}">
      <material>Gazebo/${color}</material>
    </gazebo>
  </xacro:macro>


   <!-- Tilting double rotor unit link and joint. -->
  <xacro:macro name="double_tilt_unit_minimal"
    params="robot_namespace direction_upper direction_lower parent mass_rotor mass_tilt_unit rotor_offset_top motor_number lower_start_index color mesh mesh_tilt_unit *origin *inertia">

    <!-- Rotor tilt_unit -->
    <joint name="${robot_namespace}/tilt_unit_${motor_number}_revolutejoint" type="continuous">
      <xacro:insert_block name="origin" />
      <axis xyz="1 0 0" />
      <parent link="${parent}" />
      <child link="${namespace}/tilt_unit_${motor_number}" />
    </joint>

    <gazebo reference="${robot_namespace}/tilt_unit_${motor_number}_revolutejoint">
      <provideFeedback>true</provideFeedback>
    </gazebo>

    <link name="${namespace}/tilt_unit_${motor_number}">
      <inertial>
        <mass value="${mass_tilt_unit}" /> <!-- [kg] -->
        <xacro:insert_block name="tilt_unit_inertia" />
      </inertial>
      <visual>
        <geometry>
            <mesh filename="${mesh_tilt_unit}"
              scale="1 1 1" />
        </geometry>
      </visual>
      <collision>
        <geometry>
          <box size="0.005 0.005 0.005"  /> <!-- [m] -->
        </geometry>
      </collision>
    </link>

    <gazebo reference="${namespace}/tilt_unit_${motor_number}">
      <material>Gazebo/White</material>
    </gazebo>

    <!-- Upper Rotor -->
    <joint name="rotor_${motor_number}_joint" type="continuous">
      <origin xyz="0 0 ${rotor_offset_top}" rpy="0 0 0" />
      <axis xyz="0 0 1" />
      <parent link="${namespace}/tilt_unit_${motor_number}" />
      <child link="rotor_${motor_number}" />
    </joint>

    <link name="rotor_${motor_number}">
      <inertial>
        <mass value="${mass_rotor}" /> <!-- [kg] -->
        <xacro:insert_block name="inertia" />
      </inertial>
      <visual>
        <geometry>
          <mesh filename="package://rotors_description/meshes/${mesh}_${direction_upper}.dae"
            scale="${radius_rotor} ${radius_rotor} ${radius_rotor}" />
        </geometry>
      </visual>
      <collision>
        <geometry>
          <cylinder length="0.005" radius="${radius_rotor}" /> <!-- [m] -->
        </geometry>
      </collision>
    </link>

    <gazebo reference="rotor_${motor_number}">
      <material>Gazebo/${color}</material>
    </gazebo>

    <!-- Lower Rotor -->
    <joint name="rotor_${motor_number+lower_start_index}_joint" type="continuous">
      <origin xyz="0 0 ${-rotor_offset_top}" rpy="0 0 0" />
      <axis xyz="0 0 1" />
      <parent link="${namespace}/tilt_unit_${motor_number}" />
      <child link="rotor_${motor_number+lower_start_index}" />
    </joint>

    <link name="rotor_${motor_number+lower_start_index}">
      <inertial>
        <mass value="${mass_rotor}" /> <!-- [kg] -->
        <xacro:insert_block name="inertia" />
      </inertial>
      <visual>
        <geometry>
          <mesh filename="package://rotors_description/meshes/${mesh}_${direction_lower}.dae"
            scale="${radius_rotor} ${radius_rotor} ${radius_rotor}" />
        </geometry>
      </visual>
      <collision>
        <geometry>
          <cylinder length="0.005" radius="${radius_rotor}" /> <!-- [m] -->
        </geometry>
      </collision>
    </link>

    <gazebo reference="rotor_${motor_number+lower_start_index}">
      <material>Gazebo/${color}</material>
    </gazebo>
  </xacro:macro>

</robot>
