<sdf version='1.4'>
  <world name='default'>
    <plugin name='gazebo_octomap' filename='librotors_gazebo_octomap_plugin.so'/>
    <light name='sun' type='directional'>
      <cast_shadows>1</cast_shadows>
      <pose>0 0 10 0 -0 0</pose>
      <diffuse>0.8 0.8 0.8 1</diffuse>
      <specular>0.2 0.2 0.2 1</specular>
      <attenuation>
        <range>1000</range>
        <constant>0.9</constant>
        <linear>0.01</linear>
        <quadratic>0.001</quadratic>
      </attenuation>
      <direction>-0.5 0.1 -0.9</direction>
    </light>
    <physics type='ode'>
      <ode>
        <solver>
          <type>quick</type>
          <iters>1000</iters>
          <sor>1.3</sor>
        </solver>
        <constraints>
          <cfm>0</cfm>
          <erp>0.2</erp>
          <contact_max_correcting_vel>100</contact_max_correcting_vel>
          <contact_surface_layer>0.001</contact_surface_layer>
        </constraints>
      </ode>
      <max_step_size>0.01</max_step_size>
      <real_time_factor>1</real_time_factor>
      <real_time_update_rate>100</real_time_update_rate>
      <gravity>0 0 -9.8</gravity>
    </physics>
    <scene>
      <ambient>0.4 0.4 0.4 1</ambient>
      <background>0.7 0.7 0.7 1</background>
      <shadows>1</shadows>
    </scene>
    <spherical_coordinates>
      <surface_model>EARTH_WGS84</surface_model>
      <latitude_deg>0</latitude_deg>
      <longitude_deg>0</longitude_deg>
      <elevation>0</elevation>
      <heading_deg>0</heading_deg>
    </spherical_coordinates>
    <model name='Dumpster'>
      <link name='link'>
        <collision name='collision'>
          <geometry>
            <mesh>
              <uri>model://dumpster/meshes/dumpster.dae</uri>
            </mesh>
          </geometry>
          <max_contacts>10</max_contacts>
          <surface>
            <bounce/>
            <friction>
              <ode/>
            </friction>
            <contact>
              <ode/>
            </contact>
          </surface>
        </collision>
        <visual name='visual'>
          <geometry>
            <mesh>
              <uri>model://dumpster/meshes/dumpster.dae</uri>
            </mesh>
          </geometry>
          <material>
            <script>
              <uri>model://dumpster/materials/scripts</uri>
              <uri>model://dumpster/materials/textures</uri>
              <name>Dumpster/Diffuse</name>
            </script>
          </material>
        </visual>
        <velocity_decay>
          <linear>0</linear>
          <angular>0</angular>
        </velocity_decay>
        <self_collide>0</self_collide>
        <inertial>
          <inertia>
            <ixx>1</ixx>
            <ixy>0</ixy>
            <ixz>0</ixz>
            <iyy>1</iyy>
            <iyz>0</iyz>
            <izz>1</izz>
          </inertia>
          <mass>1</mass>
        </inertial>
        <kinematic>0</kinematic>
        <gravity>1</gravity>
      </link>
      <pose>-8.5 -12 0 0 -0 0</pose>
      <static>0</static>
    </model>
    <model name='drc_practice_yellow_parking_block'>
      <static>1</static>
      <link name='link'>
        <visual name='visual'>
          <geometry>
            <mesh>
              <uri>model://drc_practice_yellow_parking_block/meshes/block.dae</uri>
            </mesh>
          </geometry>
        </visual>
        <collision name='collision'>
          <geometry>
            <mesh>
              <uri>model://drc_practice_yellow_parking_block/meshes/block.dae</uri>
            </mesh>
          </geometry>
          <max_contacts>10</max_contacts>
          <surface>
            <bounce/>
            <friction>
              <ode/>
            </friction>
            <contact>
              <ode/>
            </contact>
          </surface>
        </collision>
        <velocity_decay>
          <linear>0</linear>
          <angular>0</angular>
        </velocity_decay>
        <self_collide>0</self_collide>
        <kinematic>0</kinematic>
        <gravity>1</gravity>
      </link>
      <pose>-5 0 0 0 -0 0</pose>
    </model>
    <model name='drc_practice_yellow_parking_block_0'>
      <static>1</static>
      <link name='link'>
        <visual name='visual'>
          <geometry>
            <mesh>
              <uri>model://drc_practice_yellow_parking_block/meshes/block.dae</uri>
            </mesh>
          </geometry>
        </visual>
        <collision name='collision'>
          <geometry>
            <mesh>
              <uri>model://drc_practice_yellow_parking_block/meshes/block.dae</uri>
            </mesh>
          </geometry>
          <max_contacts>10</max_contacts>
          <surface>
            <bounce/>
            <friction>
              <ode/>
            </friction>
            <contact>
              <ode/>
            </contact>
          </surface>
        </collision>
        <velocity_decay>
          <linear>0</linear>
          <angular>0</angular>
        </velocity_decay>
        <self_collide>0</self_collide>
        <kinematic>0</kinematic>
        <gravity>1</gravity>
      </link>
      <pose>-5 -2.5 0 0 -0 0</pose>
    </model>
    <model name='drc_practice_yellow_parking_block_1'>
      <static>1</static>
      <link name='link'>
        <visual name='visual'>
          <geometry>
            <mesh>
              <uri>model://drc_practice_yellow_parking_block/meshes/block.dae</uri>
            </mesh>
          </geometry>
        </visual>
        <collision name='collision'>
          <geometry>
            <mesh>
              <uri>model://drc_practice_yellow_parking_block/meshes/block.dae</uri>
            </mesh>
          </geometry>
          <max_contacts>10</max_contacts>
          <surface>
            <bounce/>
            <friction>
              <ode/>
            </friction>
            <contact>
              <ode/>
            </contact>
          </surface>
        </collision>
        <velocity_decay>
          <linear>0</linear>
          <angular>0</angular>
        </velocity_decay>
        <self_collide>0</self_collide>
        <kinematic>0</kinematic>
        <gravity>1</gravity>
      </link>
      <pose>-5 2.5 0 0 -0 0</pose>
    </model>
    <model name='drc_practice_yellow_parking_block_2'>
      <static>1</static>
      <link name='link'>
        <visual name='visual'>
          <geometry>
            <mesh>
              <uri>model://drc_practice_yellow_parking_block/meshes/block.dae</uri>
            </mesh>
          </geometry>
        </visual>
        <collision name='collision'>
          <geometry>
            <mesh>
              <uri>model://drc_practice_yellow_parking_block/meshes/block.dae</uri>
            </mesh>
          </geometry>
          <max_contacts>10</max_contacts>
          <surface>
            <bounce/>
            <friction>
              <ode/>
            </friction>
            <contact>
              <ode/>
            </contact>
          </surface>
        </collision>
        <velocity_decay>
          <linear>0</linear>
          <angular>0</angular>
        </velocity_decay>
        <self_collide>0</self_collide>
        <kinematic>0</kinematic>
        <gravity>1</gravity>
      </link>
      <pose>-4 2.5 0 0 -0 0</pose>
    </model>
    <model name='drc_practice_yellow_parking_block_3'>
      <static>1</static>
      <link name='link'>
        <visual name='visual'>
          <geometry>
            <mesh>
              <uri>model://drc_practice_yellow_parking_block/meshes/block.dae</uri>
            </mesh>
          </geometry>
        </visual>
        <collision name='collision'>
          <geometry>
            <mesh>
              <uri>model://drc_practice_yellow_parking_block/meshes/block.dae</uri>
            </mesh>
          </geometry>
          <max_contacts>10</max_contacts>
          <surface>
            <bounce/>
            <friction>
              <ode/>
            </friction>
            <contact>
              <ode/>
            </contact>
          </surface>
        </collision>
        <velocity_decay>
          <linear>0</linear>
          <angular>0</angular>
        </velocity_decay>
        <self_collide>0</self_collide>
        <kinematic>0</kinematic>
        <gravity>1</gravity>
      </link>
      <pose>-4 0 0 0 -0 0</pose>
    </model>
    <model name='drc_practice_yellow_parking_block_4'>
      <static>1</static>
      <link name='link'>
        <visual name='visual'>
          <geometry>
            <mesh>
              <uri>model://drc_practice_yellow_parking_block/meshes/block.dae</uri>
            </mesh>
          </geometry>
        </visual>
        <collision name='collision'>
          <geometry>
            <mesh>
              <uri>model://drc_practice_yellow_parking_block/meshes/block.dae</uri>
            </mesh>
          </geometry>
          <max_contacts>10</max_contacts>
          <surface>
            <bounce/>
            <friction>
              <ode/>
            </friction>
            <contact>
              <ode/>
            </contact>
          </surface>
        </collision>
        <velocity_decay>
          <linear>0</linear>
          <angular>0</angular>
        </velocity_decay>
        <self_collide>0</self_collide>
        <kinematic>0</kinematic>
        <gravity>1</gravity>
      </link>
      <pose>-4 -2.5 0 0 -0 0</pose>
    </model>
    <model name='House 1'>
      <static>1</static>
      <link name='link'>
        <collision name='collision'>
          <geometry>
            <mesh>
              <uri>model://house_1/meshes/house_1.dae</uri>
            </mesh>
          </geometry>
          <max_contacts>10</max_contacts>
          <surface>
            <bounce/>
            <friction>
              <ode/>
            </friction>
            <contact>
              <ode/>
            </contact>
          </surface>
        </collision>
        <visual name='visual'>
          <geometry>
            <mesh>
              <uri>model://house_1/meshes/house_1.dae</uri>
            </mesh>
          </geometry>
          <material>
            <script>
              <uri>model://house_1/materials/scripts</uri>
              <uri>model://house_1/materials/textures</uri>
              <name>House_1/Diffuse</name>
            </script>
            <shader type='normal_map_object_space'>
              <normal_map>House_1_Normal.png</normal_map>
            </shader>
          </material>
        </visual>
        <velocity_decay>
          <linear>0</linear>
          <angular>0</angular>
        </velocity_decay>
        <self_collide>0</self_collide>
        <kinematic>0</kinematic>
        <gravity>1</gravity>
      </link>
      <pose>13 16 0 0 -0 0</pose>
    </model>
    <model name='House 2'>
      <static>1</static>
      <link name='link'>
        <collision name='collision'>
          <geometry>
            <mesh>
              <uri>model://house_2/meshes/house_2.dae</uri>
            </mesh>
          </geometry>
          <max_contacts>10</max_contacts>
          <surface>
            <bounce/>
            <friction>
              <ode/>
            </friction>
            <contact>
              <ode/>
            </contact>
          </surface>
        </collision>
        <visual name='visual'>
          <geometry>
            <mesh>
              <uri>model://house_2/meshes/house_2.dae</uri>
            </mesh>
          </geometry>
          <material>
            <script>
              <uri>model://house_2/materials/scripts</uri>
              <uri>model://house_2/materials/textures</uri>
              <uri>model://house_1/materials/textures</uri>
              <name>House_2/Diffuse</name>
            </script>
            <shader type='normal_map_object_space'>
              <normal_map>model://house_1/materials/textures/House_1_Normal.png</normal_map>
            </shader>
          </material>
        </visual>
        <velocity_decay>
          <linear>0</linear>
          <angular>0</angular>
        </velocity_decay>
        <self_collide>0</self_collide>
        <kinematic>0</kinematic>
        <gravity>1</gravity>
      </link>
      <pose>0 15 0 0 -0 0</pose>
    </model>
    <model name='House 3'>
      <static>1</static>
      <link name='link'>
        <collision name='collision'>
          <geometry>
            <mesh>
              <uri>model://house_3/meshes/house_3.dae</uri>
            </mesh>
          </geometry>
          <max_contacts>10</max_contacts>
          <surface>
            <bounce/>
            <friction>
              <ode/>
            </friction>
            <contact>
              <ode/>
            </contact>
          </surface>
        </collision>
        <visual name='visual'>
          <geometry>
            <mesh>
              <uri>model://house_3/meshes/house_3.dae</uri>
            </mesh>
          </geometry>
          <material>
            <script>
              <uri>model://house_3/materials/scripts</uri>
              <uri>model://house_3/materials/textures</uri>
              <uri>model://house_1/materials/textures</uri>
              <name>House_3/Diffuse</name>
            </script>
            <shader type='normal_map_object_space'>
              <normal_map>model://house_1/materials/textures/House_1_Normal.png</normal_map>
            </shader>
          </material>
        </visual>
        <velocity_decay>
          <linear>0</linear>
          <angular>0</angular>
        </velocity_decay>
        <self_collide>0</self_collide>
        <kinematic>0</kinematic>
        <gravity>1</gravity>
      </link>
      <pose>-8 14 0 0 -0 0</pose>
    </model>
    <model name='mud_box'>
      <static>1</static>
      <link name='link'>
        <collision name='collision'>
          <geometry>
            <box>
              <size>8 10 0.2</size>
            </box>
          </geometry>
          <max_contacts>10</max_contacts>
          <surface>
            <bounce/>
            <friction>
              <ode/>
            </friction>
            <contact>
              <ode/>
            </contact>
          </surface>
        </collision>
        <visual name='visual_1'>
          <pose>-2 2.5 0 0 -0 0</pose>
          <cast_shadows>0</cast_shadows>
          <geometry>
            <box>
              <size>4 5 0.2</size>
            </box>
          </geometry>
          <material>
            <script>
              <uri>model://mud_box/materials/scripts</uri>
              <uri>model://mud_box/materials/textures</uri>
              <name>vrc/mud</name>
            </script>
          </material>
        </visual>
        <visual name='visual_2'>
          <pose>2 2.5 0 0 -0 0</pose>
          <cast_shadows>0</cast_shadows>
          <geometry>
            <box>
              <size>4 5 0.2</size>
            </box>
          </geometry>
          <material>
            <script>
              <uri>model://mud_box/materials/scripts</uri>
              <uri>model://mud_box/materials/textures</uri>
              <name>vrc/mud</name>
            </script>
          </material>
        </visual>
        <visual name='visual_3'>
          <pose>2 -2.5 0 0 -0 0</pose>
          <cast_shadows>0</cast_shadows>
          <geometry>
            <box>
              <size>4 5 0.2</size>
            </box>
          </geometry>
          <material>
            <script>
              <uri>model://mud_box/materials/scripts</uri>
              <uri>model://mud_box/materials/textures</uri>
              <name>vrc/mud</name>
            </script>
          </material>
        </visual>
        <visual name='visual_4'>
          <pose>-2 -2.5 0 0 -0 0</pose>
          <cast_shadows>0</cast_shadows>
          <geometry>
            <box>
              <size>4 5 0.2</size>
            </box>
          </geometry>
          <material>
            <script>
              <uri>model://mud_box/materials/scripts</uri>
              <uri>model://mud_box/materials/textures</uri>
              <name>vrc/mud</name>
            </script>
          </material>
        </visual>
        <velocity_decay>
          <linear>0</linear>
          <angular>0</angular>
        </velocity_decay>
        <self_collide>0</self_collide>
        <kinematic>0</kinematic>
        <gravity>1</gravity>
      </link>
      <pose>-16.1 -21 0 0 -0 0</pose>
    </model>
    <model name='ladder'>
      <static>1</static>
      <link name='link'>
        <collision name='step0'>
          <pose>0 -1 0.3 0 -0 0</pose>
          <geometry>
            <box>
              <size>0.9 0.1016 0.0381</size>
            </box>
          </geometry>
          <max_contacts>10</max_contacts>
          <surface>
            <bounce/>
            <friction>
              <ode/>
            </friction>
            <contact>
              <ode/>
            </contact>
          </surface>
        </collision>
        <collision name='step1'>
          <pose>0 -0.79106 0.59054 0 -0 0</pose>
          <geometry>
            <box>
              <size>0.9 0.1016 0.0381</size>
            </box>
          </geometry>
          <max_contacts>10</max_contacts>
          <surface>
            <bounce/>
            <friction>
              <ode/>
            </friction>
            <contact>
              <ode/>
            </contact>
          </surface>
        </collision>
        <collision name='step2'>
          <pose>0 -0.61509 0.89508 0 -0 0</pose>
          <geometry>
            <box>
              <size>0.9 0.1016 0.0381</size>
            </box>
          </geometry>
          <max_contacts>10</max_contacts>
          <surface>
            <bounce/>
            <friction>
              <ode/>
            </friction>
            <contact>
              <ode/>
            </contact>
          </surface>
        </collision>
        <collision name='step3'>
          <pose>0 -0.43912 1.19962 0 -0 0</pose>
          <geometry>
            <box>
              <size>0.9 0.1016 0.0381</size>
            </box>
          </geometry>
          <max_contacts>10</max_contacts>
          <surface>
            <bounce/>
            <friction>
              <ode/>
            </friction>
            <contact>
              <ode/>
            </contact>
          </surface>
        </collision>
        <collision name='step4'>
          <pose>0 -0.26315 1.50416 0 -0 0</pose>
          <geometry>
            <box>
              <size>0.9 0.1016 0.0381</size>
            </box>
          </geometry>
          <max_contacts>10</max_contacts>
          <surface>
            <bounce/>
            <friction>
              <ode/>
            </friction>
            <contact>
              <ode/>
            </contact>
          </surface>
        </collision>
        <collision name='step5'>
          <pose>0 -0.08718 1.8087 0 -0 0</pose>
          <geometry>
            <box>
              <size>0.9 0.1016 0.0381</size>
            </box>
          </geometry>
          <max_contacts>10</max_contacts>
          <surface>
            <bounce/>
            <friction>
              <ode/>
            </friction>
            <contact>
              <ode/>
            </contact>
          </surface>
        </collision>
        <collision name='step6'>
          <pose>0 0.08879 2.11324 0 -0 0</pose>
          <geometry>
            <box>
              <size>0.9 0.1016 0.0381</size>
            </box>
          </geometry>
          <max_contacts>10</max_contacts>
          <surface>
            <bounce/>
            <friction>
              <ode/>
            </friction>
            <contact>
              <ode/>
            </contact>
          </surface>
        </collision>
        <collision name='step7'>
          <pose>0 0.26476 2.41778 0 -0 0</pose>
          <geometry>
            <box>
              <size>0.9 0.1016 0.0381</size>
            </box>
          </geometry>
          <max_contacts>10</max_contacts>
          <surface>
            <bounce/>
            <friction>
              <ode/>
            </friction>
            <contact>
              <ode/>
            </contact>
          </surface>
        </collision>
        <collision name='landing'>
          <pose>0 0.73039 2.72432 0 -0 0</pose>
          <geometry>
            <box>
              <size>0.9 0.6096 0.0381</size>
            </box>
          </geometry>
          <max_contacts>10</max_contacts>
          <surface>
            <bounce/>
            <friction>
              <ode/>
            </friction>
            <contact>
              <ode/>
            </contact>
          </surface>
        </collision>
        <collision name='left_side_wall'>
          <pose>-0.43217 -0.37451 1.3386 1.0472 -0 0</pose>
          <geometry>
            <box>
              <size>0.0508 3.16758 0.13</size>
            </box>
          </geometry>
          <max_contacts>10</max_contacts>
          <surface>
            <bounce/>
            <friction>
              <ode/>
            </friction>
            <contact>
              <ode/>
            </contact>
          </surface>
        </collision>
        <collision name='left_side_landing_wall'>
          <pose>-0.43217 0.69819 2.667 0 -0 0</pose>
          <geometry>
            <box>
              <size>0.0508 0.67401 0.1524</size>
            </box>
          </geometry>
          <max_contacts>10</max_contacts>
          <surface>
            <bounce/>
            <friction>
              <ode/>
            </friction>
            <contact>
              <ode/>
            </contact>
          </surface>
        </collision>
        <collision name='left_railing_landing_3'>
          <pose>-0.433355 0.66933 3.81 1.5707 -0 0</pose>
          <geometry>
            <cylinder>
              <radius>0.02413</radius>
              <length>0.73172</length>
            </cylinder>
          </geometry>
          <max_contacts>10</max_contacts>
          <surface>
            <bounce/>
            <friction>
              <ode/>
            </friction>
            <contact>
              <ode/>
            </contact>
          </surface>
        </collision>
        <collision name='left_railing_landing_2'>
          <pose>-0.433355 0.73166 3.5433 1.5707 -0 0</pose>
          <geometry>
            <cylinder>
              <radius>0.02413</radius>
              <length>0.5588</length>
            </cylinder>
          </geometry>
          <max_contacts>10</max_contacts>
          <surface>
            <bounce/>
            <friction>
              <ode/>
            </friction>
            <contact>
              <ode/>
            </contact>
          </surface>
        </collision>
        <collision name='left_railing_landing_1'>
          <pose>-0.433355 0.73166 3.2766 1.5707 -0 0</pose>
          <geometry>
            <cylinder>
              <radius>0.02413</radius>
              <length>0.5588</length>
            </cylinder>
          </geometry>
          <max_contacts>10</max_contacts>
          <surface>
            <bounce/>
            <friction>
              <ode/>
            </friction>
            <contact>
              <ode/>
            </contact>
          </surface>
        </collision>
        <collision name='left_railing_landing_0'>
          <pose>-0.433355 0.73166 3.0099 1.5707 -0 0</pose>
          <geometry>
            <cylinder>
              <radius>0.02413</radius>
              <length>0.5588</length>
            </cylinder>
          </geometry>
          <max_contacts>10</max_contacts>
          <surface>
            <bounce/>
            <friction>
              <ode/>
            </friction>
            <contact>
              <ode/>
            </contact>
          </surface>
        </collision>
        <collision name='left_railing_landing_upright_back'>
          <pose>-0.433355 1.01088 3.2766 0 -0 0</pose>
          <geometry>
            <cylinder>
              <radius>0.02413</radius>
              <length>1.0668</length>
            </cylinder>
          </geometry>
          <max_contacts>10</max_contacts>
          <surface>
            <bounce/>
            <friction>
              <ode/>
            </friction>
            <contact>
              <ode/>
            </contact>
          </surface>
        </collision>
        <collision name='left_railing_landing_upright_front'>
          <pose>-0.433355 0.45208 3.2766 0 -0 0</pose>
          <geometry>
            <cylinder>
              <radius>0.02413</radius>
              <length>1.0668</length>
            </cylinder>
          </geometry>
          <max_contacts>10</max_contacts>
          <surface>
            <bounce/>
            <friction>
              <ode/>
            </friction>
            <contact>
              <ode/>
            </contact>
          </surface>
        </collision>
        <collision name='left_railing_upright_4'>
          <pose>-0.433355 0.0699 2.80986 1.03414 -0 0</pose>
          <geometry>
            <cylinder>
              <radius>0.02413</radius>
              <length>0.57</length>
            </cylinder>
          </geometry>
          <max_contacts>10</max_contacts>
          <surface>
            <bounce/>
            <friction>
              <ode/>
            </friction>
            <contact>
              <ode/>
            </contact>
          </surface>
        </collision>
        <collision name='left_railing_upright_3'>
          <pose>-0.433355 -0.31006 2.15169 1.03414 -0 0</pose>
          <geometry>
            <cylinder>
              <radius>0.02413</radius>
              <length>0.57</length>
            </cylinder>
          </geometry>
          <max_contacts>10</max_contacts>
          <surface>
            <bounce/>
            <friction>
              <ode/>
            </friction>
            <contact>
              <ode/>
            </contact>
          </surface>
        </collision>
        <collision name='left_railing_upright_2'>
          <pose>-0.433355 -0.6911 1.49172 1.03414 -0 0</pose>
          <geometry>
            <cylinder>
              <radius>0.02413</radius>
              <length>0.57</length>
            </cylinder>
          </geometry>
          <max_contacts>10</max_contacts>
          <surface>
            <bounce/>
            <friction>
              <ode/>
            </friction>
            <contact>
              <ode/>
            </contact>
          </surface>
        </collision>
        <collision name='left_railing_upright_1'>
          <pose>-0.433355 -1.0732 0.82995 1.03414 -0 0</pose>
          <geometry>
            <cylinder>
              <radius>0.02413</radius>
              <length>0.57</length>
            </cylinder>
          </geometry>
          <max_contacts>10</max_contacts>
          <surface>
            <bounce/>
            <friction>
              <ode/>
            </friction>
            <contact>
              <ode/>
            </contact>
          </surface>
        </collision>
        <collision name='left_railing_upright_0'>
          <pose>-0.433355 -1.45316 0.17179 1.03414 -0 0</pose>
          <geometry>
            <cylinder>
              <radius>0.02413</radius>
              <length>0.57</length>
            </cylinder>
          </geometry>
          <max_contacts>10</max_contacts>
          <surface>
            <bounce/>
            <friction>
              <ode/>
            </friction>
            <contact>
              <ode/>
            </contact>
          </surface>
        </collision>
        <collision name='left_railing_long'>
          <pose>-0.433355 -0.781 1.9068 -0.523503 0 0</pose>
          <geometry>
            <cylinder>
              <radius>0.02413</radius>
              <length>4.42295</length>
            </cylinder>
          </geometry>
          <max_contacts>10</max_contacts>
          <surface>
            <bounce/>
            <friction>
              <ode/>
            </friction>
            <contact>
              <ode/>
            </contact>
          </surface>
        </collision>
        <collision name='right_side_wall'>
          <pose>0.43217 -0.37451 1.3386 1.0472 -0 0</pose>
          <geometry>
            <box>
              <size>0.0508 3.16758 0.13</size>
            </box>
          </geometry>
          <max_contacts>10</max_contacts>
          <surface>
            <bounce/>
            <friction>
              <ode/>
            </friction>
            <contact>
              <ode/>
            </contact>
          </surface>
        </collision>
        <collision name='right_side_landing_wall'>
          <pose>0.43217 0.69819 2.667 0 -0 0</pose>
          <geometry>
            <box>
              <size>0.0508 0.67401 0.1524</size>
            </box>
          </geometry>
          <max_contacts>10</max_contacts>
          <surface>
            <bounce/>
            <friction>
              <ode/>
            </friction>
            <contact>
              <ode/>
            </contact>
          </surface>
        </collision>
        <collision name='right_railing_landing_3'>
          <pose>0.433355 0.66933 3.81 1.5707 -0 0</pose>
          <geometry>
            <cylinder>
              <radius>0.02413</radius>
              <length>0.73172</length>
            </cylinder>
          </geometry>
          <max_contacts>10</max_contacts>
          <surface>
            <bounce/>
            <friction>
              <ode/>
            </friction>
            <contact>
              <ode/>
            </contact>
          </surface>
        </collision>
        <collision name='right_railing_landing_2'>
          <pose>0.433355 0.73166 3.5433 1.5707 -0 0</pose>
          <geometry>
            <cylinder>
              <radius>0.02413</radius>
              <length>0.5588</length>
            </cylinder>
          </geometry>
          <max_contacts>10</max_contacts>
          <surface>
            <bounce/>
            <friction>
              <ode/>
            </friction>
            <contact>
              <ode/>
            </contact>
          </surface>
        </collision>
        <collision name='right_railing_landing_1'>
          <pose>0.433355 0.73166 3.2766 1.5707 -0 0</pose>
          <geometry>
            <cylinder>
              <radius>0.02413</radius>
              <length>0.5588</length>
            </cylinder>
          </geometry>
          <max_contacts>10</max_contacts>
          <surface>
            <bounce/>
            <friction>
              <ode/>
            </friction>
            <contact>
              <ode/>
            </contact>
          </surface>
        </collision>
        <collision name='right_railing_landing_0'>
          <pose>0.433355 0.73166 3.0099 1.5707 -0 0</pose>
          <geometry>
            <cylinder>
              <radius>0.02413</radius>
              <length>0.5588</length>
            </cylinder>
          </geometry>
          <max_contacts>10</max_contacts>
          <surface>
            <bounce/>
            <friction>
              <ode/>
            </friction>
            <contact>
              <ode/>
            </contact>
          </surface>
        </collision>
        <collision name='right_railing_landing_upright_back'>
          <pose>0.433355 1.01088 3.2766 0 -0 0</pose>
          <geometry>
            <cylinder>
              <radius>0.02413</radius>
              <length>1.0668</length>
            </cylinder>
          </geometry>
          <max_contacts>10</max_contacts>
          <surface>
            <bounce/>
            <friction>
              <ode/>
            </friction>
            <contact>
              <ode/>
            </contact>
          </surface>
        </collision>
        <collision name='right_railing_landing_upright_front'>
          <pose>0.433355 0.45208 3.2766 0 -0 0</pose>
          <geometry>
            <cylinder>
              <radius>0.02413</radius>
              <length>1.0668</length>
            </cylinder>
          </geometry>
          <max_contacts>10</max_contacts>
          <surface>
            <bounce/>
            <friction>
              <ode/>
            </friction>
            <contact>
              <ode/>
            </contact>
          </surface>
        </collision>
        <collision name='right_railing_upright_4'>
          <pose>0.433355 0.0699 2.80986 1.03414 -0 0</pose>
          <geometry>
            <cylinder>
              <radius>0.02413</radius>
              <length>0.57</length>
            </cylinder>
          </geometry>
          <max_contacts>10</max_contacts>
          <surface>
            <bounce/>
            <friction>
              <ode/>
            </friction>
            <contact>
              <ode/>
            </contact>
          </surface>
        </collision>
        <collision name='right_railing_upright_3'>
          <pose>0.433355 -0.31006 2.15169 1.03414 -0 0</pose>
          <geometry>
            <cylinder>
              <radius>0.02413</radius>
              <length>0.57</length>
            </cylinder>
          </geometry>
          <max_contacts>10</max_contacts>
          <surface>
            <bounce/>
            <friction>
              <ode/>
            </friction>
            <contact>
              <ode/>
            </contact>
          </surface>
        </collision>
        <collision name='right_railing_upright_2'>
          <pose>0.433355 -0.6911 1.49172 1.03414 -0 0</pose>
          <geometry>
            <cylinder>
              <radius>0.02413</radius>
              <length>0.57</length>
            </cylinder>
          </geometry>
          <max_contacts>10</max_contacts>
          <surface>
            <bounce/>
            <friction>
              <ode/>
            </friction>
            <contact>
              <ode/>
            </contact>
          </surface>
        </collision>
        <collision name='right_railing_upright_1'>
          <pose>0.433355 -1.0732 0.82995 1.03414 -0 0</pose>
          <geometry>
            <cylinder>
              <radius>0.02413</radius>
              <length>0.57</length>
            </cylinder>
          </geometry>
          <max_contacts>10</max_contacts>
          <surface>
            <bounce/>
            <friction>
              <ode/>
            </friction>
            <contact>
              <ode/>
            </contact>
          </surface>
        </collision>
        <collision name='right_railing_upright_0'>
          <pose>0.433355 -1.45316 0.17179 1.03414 -0 0</pose>
          <geometry>
            <cylinder>
              <radius>0.02413</radius>
              <length>0.57</length>
            </cylinder>
          </geometry>
          <max_contacts>10</max_contacts>
          <surface>
            <bounce/>
            <friction>
              <ode/>
            </friction>
            <contact>
              <ode/>
            </contact>
          </surface>
        </collision>
        <collision name='right_railing_long'>
          <pose>0.433355 -0.781 1.9068 -0.523503 0 0</pose>
          <geometry>
            <cylinder>
              <radius>0.02413</radius>
              <length>4.42295</length>
            </cylinder>
          </geometry>
          <max_contacts>10</max_contacts>
          <surface>
            <bounce/>
            <friction>
              <ode/>
            </friction>
            <contact>
              <ode/>
            </contact>
          </surface>
        </collision>
        <visual name='visual'>
          <geometry>
            <mesh>
              <uri>model://drc_practice_ladder/meshes/ladder.dae</uri>
            </mesh>
          </geometry>
        </visual>
        <velocity_decay>
          <linear>0</linear>
          <angular>0</angular>
        </velocity_decay>
        <self_collide>0</self_collide>
        <kinematic>0</kinematic>
        <gravity>1</gravity>
      </link>
      <pose>-13 -13 0 0 -0 0</pose>
    </model>
    <model name='grey_wall_0'>
      <static>1</static>
      <link name='link'>
        <pose>0 0 1.4 0 -0 0</pose>
        <collision name='collision'>
          <geometry>
            <box>
              <size>7.5 0.2 2.8</size>
            </box>
          </geometry>
          <max_contacts>10</max_contacts>
          <surface>
            <bounce/>
            <friction>
              <ode/>
            </friction>
            <contact>
              <ode/>
            </contact>
          </surface>
        </collision>
        <visual name='visual'>
          <cast_shadows>0</cast_shadows>
          <geometry>
            <box>
              <size>7.5 0.2 2.8</size>
            </box>
          </geometry>
          <material>
            <script>
              <uri>model://grey_wall/materials/scripts</uri>
              <uri>model://grey_wall/materials/textures</uri>
              <name>vrc/grey_wall</name>
            </script>
          </material>
        </visual>
        <velocity_decay>
          <linear>0</linear>
          <angular>0</angular>
        </velocity_decay>
        <self_collide>0</self_collide>
        <kinematic>0</kinematic>
        <gravity>1</gravity>
      </link>
      <pose>-12.15 -19.7 0 0 -0 0</pose>
    </model>
    <state world_name='default'>
      <sim_time>1765 290000000</sim_time>
      <real_time>980 450177634</real_time>
      <wall_time>1430246609 334093932</wall_time>
      <model name='BuildingDefaultName'>
        <pose>0 0 0 0 -0 0</pose>
        <link name='__default__'>
          <pose>0 0 0 0 -0 0</pose>
          <velocity>0 0 0 0 -0 0</velocity>
          <acceleration>0 0 0 0 -0 0</acceleration>
          <wrench>0 0 0 0 -0 0</wrench>
        </link>
      </model>
      <model name='Dumpster'>
        <pose>173.628 17.8615 0.010918 -0 -0 -2.15379</pose>
        <link name='link'>
          <pose>173.628 17.8615 0.010918 -0 -0 -2.15379</pose>
          <velocity>0 0 0 0 -0 0</velocity>
          <acceleration>0 0 0 0 -0 0</acceleration>
          <wrench>0 0 0 0 -0 0</wrench>
        </link>
      </model>
      <model name='House 1'>
        <pose>13 16 0 0 -0 0</pose>
        <link name='link'>
          <pose>13 16 0 0 -0 0</pose>
          <velocity>0 0 0 0 -0 0</velocity>
          <acceleration>0 0 0 0 -0 0</acceleration>
          <wrench>0 0 0 0 -0 0</wrench>
        </link>
      </model>
      <model name='House 2'>
        <pose>0 15 0 0 -0 0</pose>
        <link name='link'>
          <pose>0 15 0 0 -0 0</pose>
          <velocity>0 0 0 0 -0 0</velocity>
          <acceleration>0 0 0 0 -0 0</acceleration>
          <wrench>0 0 0 0 -0 0</wrench>
        </link>
      </model>
      <model name='House 3'>
        <pose>-8 14 0 0 -0 0</pose>
        <link name='link'>
          <pose>-8 14 0 0 -0 0</pose>
          <velocity>0 0 0 0 -0 0</velocity>
          <acceleration>0 0 0 0 -0 0</acceleration>
          <wrench>0 0 0 0 -0 0</wrench>
        </link>
      </model>
      <model name='RoboCup 3D Simulation Field_3'>
        <pose>-6 7 0 0 -0 0</pose>
        <link name='field'>
          <pose>-6 7 0.01 0 -0 0</pose>
          <velocity>0 0 0 0 -0 0</velocity>
          <acceleration>0 0 0 0 -0 0</acceleration>
          <wrench>0 0 0 0 -0 0</wrench>
        </link>
      </model>
      <model name='RoboCup 3D Simulation Field_4'>
        <pose>25 7 0 0 -0 0</pose>
        <link name='field'>
          <pose>25 7 0.01 0 -0 0</pose>
          <velocity>0 0 0 0 -0 0</velocity>
          <acceleration>0 0 0 0 -0 0</acceleration>
          <wrench>0 0 0 0 -0 0</wrench>
        </link>
      </model>
      <model name='RoboCup 3D Simulation Field_5'>
        <pose>25 -15 0 0 -0 0</pose>
        <link name='field'>
          <pose>25 -15 0.01 0 -0 0</pose>
          <velocity>0 0 0 0 -0 0</velocity>
          <acceleration>0 0 0 0 -0 0</acceleration>
          <wrench>0 0 0 0 -0 0</wrench>
        </link>
      </model>
      <model name='RoboCup 3D Simulation Field_6'>
        <pose>-6 -15 0 0 -0 0</pose>
        <link name='field'>
          <pose>-6 -15 0.01 0 -0 0</pose>
          <velocity>0 0 0 0 -0 0</velocity>
          <acceleration>0 0 0 0 -0 0</acceleration>
          <wrench>0 0 0 0 -0 0</wrench>
        </link>
      </model>
      <model name='drc_practice_yellow_parking_block'>
        <pose>-5 0 0 0 -0 0</pose>
        <link name='link'>
          <pose>-5 0 0 0 -0 0</pose>
          <velocity>0 0 0 0 -0 0</velocity>
          <acceleration>0 0 0 0 -0 0</acceleration>
          <wrench>0 0 0 0 -0 0</wrench>
        </link>
      </model>
      <model name='drc_practice_yellow_parking_block_0'>
        <pose>-5 -2.5 0 0 -0 0</pose>
        <link name='link'>
          <pose>-5 -2.5 0 0 -0 0</pose>
          <velocity>0 0 0 0 -0 0</velocity>
          <acceleration>0 0 0 0 -0 0</acceleration>
          <wrench>0 0 0 0 -0 0</wrench>
        </link>
      </model>
      <model name='drc_practice_yellow_parking_block_1'>
        <pose>-5 2.5 0 0 -0 0</pose>
        <link name='link'>
          <pose>-5 2.5 0 0 -0 0</pose>
          <velocity>0 0 0 0 -0 0</velocity>
          <acceleration>0 0 0 0 -0 0</acceleration>
          <wrench>0 0 0 0 -0 0</wrench>
        </link>
      </model>
      <model name='drc_practice_yellow_parking_block_2'>
        <pose>-4 2.5 0 0 -0 0</pose>
        <link name='link'>
          <pose>-4 2.5 0 0 -0 0</pose>
          <velocity>0 0 0 0 -0 0</velocity>
          <acceleration>0 0 0 0 -0 0</acceleration>
          <wrench>0 0 0 0 -0 0</wrench>
        </link>
      </model>
      <model name='drc_practice_yellow_parking_block_3'>
        <pose>-4 0 0 0 -0 0</pose>
        <link name='link'>
          <pose>-4 0 0 0 -0 0</pose>
          <velocity>0 0 0 0 -0 0</velocity>
          <acceleration>0 0 0 0 -0 0</acceleration>
          <wrench>0 0 0 0 -0 0</wrench>
        </link>
      </model>
      <model name='drc_practice_yellow_parking_block_4'>
        <pose>-4 -2.5 0 0 -0 0</pose>
        <link name='link'>
          <pose>-4 -2.5 0 0 -0 0</pose>
          <velocity>0 0 0 0 -0 0</velocity>
          <acceleration>0 0 0 0 -0 0</acceleration>
          <wrench>0 0 0 0 -0 0</wrench>
        </link>
      </model>
      <model name='firefly'>
        <pose>0.837556 0.284585 1.14449 0.106521 0.09838 -0.787067</pose>
        <link name='base_link'>
          <pose>0.837556 0.284585 1.14449 0.106521 0.09838 -0.787067</pose>
          <velocity>-0.042974 0.01942 -0.060674 -0.077573 0.198328 0.009441</velocity>
          <acceleration>0 0 0 0 -0 0</acceleration>
          <wrench>0 0 0 0 -0 0</wrench>
        </link>
        <link name='firefly/ground_truth/odometry_sensorgt_link'>
          <pose>0.837555 0.284585 1.14449 0.106521 0.09838 -0.787067</pose>
          <velocity>-0.042972 0.019422 -0.060676 -0.077573 0.198328 0.009441</velocity>
          <acceleration>0 0 0 0 -0 0</acceleration>
          <wrench>0 0 0 0 -0 0</wrench>
        </link>
        <link name='firefly/imu_link'>
          <pose>0.837555 0.284585 1.14449 0.106521 0.09838 -0.787067</pose>
          <velocity>-0.042972 0.019422 -0.060676 -0.077573 0.198328 0.009441</velocity>
          <acceleration>0 0 0 0 -0 0</acceleration>
          <wrench>0 0 0 0 -0 0</wrench>
        </link>
        <link name='firefly/imugt_link'>
          <pose>0.837555 0.284585 1.14449 0.106521 0.09838 -0.787067</pose>
          <velocity>-0.042972 0.019422 -0.060676 -0.077573 0.198328 0.009441</velocity>
          <acceleration>0 0 0 0 -0 0</acceleration>
          <wrench>0 0 0 0 -0 0</wrench>
        </link>
        <link name='firefly/odometry_sensor1/odometry_sensor1_link'>
          <pose>0.837555 0.284585 1.14449 0.106521 0.09838 -0.787067</pose>
          <velocity>-0.042972 0.019422 -0.060676 -0.077573 0.198328 0.009441</velocity>
          <acceleration>0 0 0 0 -0 0</acceleration>
          <wrench>0 0 0 0 -0 0</wrench>
        </link>
        <link name='firefly/vi_sensor/ground_truth/odometry_sensor_link'>
          <pose>0.907999 0.218427 1.10498 0.10812 0.197805 -0.776241</pose>
          <velocity>-0.050198 0.017006 -0.069479 -0.077573 0.198328 0.009441</velocity>
          <acceleration>0 0 0 0 -0 0</acceleration>
          <wrench>0 0 0 0 -0 0</wrench>
        </link>
        <link name='firefly/vi_sensor/imu_link'>
          <pose>0.919215 0.205706 1.11305 0.10812 0.197805 -0.776241</pose>
          <velocity>-0.048482 0.017738 -0.070733 -0.077573 0.198328 0.009441</velocity>
          <acceleration>0 0 0 0 -0 0</acceleration>
          <wrench>0 0 0 0 -0 0</wrench>
        </link>
        <link name='rotor_0'>
          <pose>1.04464 0.222674 1.17419 0.115582 0.095026 -0.721669</pose>
          <velocity>-0.036665 0.023575 -0.097013 2.59088 -1.32293 0.65106</velocity>
          <acceleration>0 0 0 0 -0 0</acceleration>
          <wrench>0 0 0 0 -0 0</wrench>
        </link>
        <link name='rotor_1'>
          <pose>0.990337 0.428581 1.20385 0.104336 0.09795 -0.820341</pose>
          <velocity>-0.032819 0.025284 -0.102199 -2.48144 1.56802 0.441599</velocity>
          <acceleration>0 0 0 0 -0 0</acceleration>
          <wrench>0 0 0 0 -0 0</wrench>
        </link>
        <link name='rotor_2'>
          <pose>0.783022 0.485155 1.21077 0.138137 0.056404 -0.422402</pose>
          <velocity>-0.031819 0.023978 -0.065457 2.58476 -1.1522 1.94244</velocity>
          <acceleration>0 0 0 0 -0 0</acceleration>
          <wrench>0 0 0 0 -0 0</wrench>
        </link>
        <link name='rotor_3'>
          <pose>0.630005 0.335822 1.18802 0.009077 -0.142299 1.43242</pose>
          <velocity>-0.034667 0.020962 -0.023529 -2.32874 0.566336 -0.473962</velocity>
          <acceleration>0 0 0 0 -0 0</acceleration>
          <wrench>0 0 0 0 -0 0</wrench>
        </link>
        <link name='rotor_4'>
          <pose>0.684303 0.129916 1.15835 -0.104449 -0.108223 2.3042</pose>
          <velocity>-0.038513 0.019252 -0.018344 2.52596 -0.118343 1.85476</velocity>
          <acceleration>0 0 0 0 -0 0</acceleration>
          <wrench>0 0 0 0 -0 0</wrench>
        </link>
        <link name='rotor_5'>
          <pose>0.891619 0.073342 1.15144 -0.080684 0.117711 -2.24963</pose>
          <velocity>-0.039513 0.020559 -0.055086 -2.32927 0.728697 0.704291</velocity>
          <acceleration>0 0 0 0 -0 0</acceleration>
          <wrench>0 0 0 0 -0 0</wrench>
        </link>
      </model>
      <model name='grey_wall_0'>
        <pose>-12.15 -19.7 0 0 0 -1.57378</pose>
        <link name='link'>
          <pose>-12.15 -19.7 1.4 0 0 -1.57378</pose>
          <velocity>0 0 0 0 -0 0</velocity>
          <acceleration>0 0 0 0 -0 0</acceleration>
          <wrench>0 0 0 0 -0 0</wrench>
        </link>
      </model>
      <model name='ladder'>
        <pose>-13.3 -15.3 0.1 0 0 -3.1415</pose>
        <link name='link'>
          <pose>-13.3 -15.3 0.1 0 0 -3.1415</pose>
          <velocity>0 0 0 0 -0 0</velocity>
          <acceleration>0 0 0 0 -0 0</acceleration>
          <wrench>0 0 0 0 -0 0</wrench>
        </link>
      </model>
      <model name='mud_box'>
        <pose>-16.1 -21 0 0 -0 0</pose>
        <link name='link'>
          <pose>12 -1 0 0 -0 0</pose>
          <velocity>0 0 0 0 -0 0</velocity>
          <acceleration>0 0 0 0 -0 0</acceleration>
          <wrench>0 0 0 0 -0 0</wrench>
        </link>
      </model>
    </state>
    <gui fullscreen='0'>
      <camera name='user_camera'>
        <pose>2.3 -6.28419 2.7824 0 0.25 1.8</pose>
        <view_controller>orbit</view_controller>
      </camera>
    </gui>
    <model name='firefly'>
      <link name='base_link'>
        <pose>0 0 0 0 -0 0</pose>
        <inertial>
          <pose>0.00797744 3.37417e-07 -0.00239305 0 -0 0</pose>
          <mass>1.63003</mass>
          <inertia>
            <ixx>0.0348681</ixx>
            <ixy>-5.91781e-08</ixy>
            <ixz>0.000358969</ixz>
            <iyy>0.0472013</iyy>
            <iyz>1.24503e-08</iyz>
            <izz>0.0989008</izz>
          </inertia>
        </inertial>
        <collision name='base_link_collision_base_link_inertia'>
          <pose>0 0 0 0 -0 0</pose>
          <geometry>
            <box>
              <size>0.1 0.1 0.16</size>
            </box>
          </geometry>
          <max_contacts>10</max_contacts>
          <surface>
            <bounce/>
            <friction>
              <ode/>
            </friction>
            <contact>
              <ode/>
            </contact>
          </surface>
        </collision>
        <collision name='base_link_collision_firefly/vi_sensor/camera_depth_link'>
          <pose>0.115574 0.055 -0.02503 0 0.1 0</pose>
          <geometry>
            <cylinder>
              <length>0.01</length>
              <radius>0.007</radius>
            </cylinder>
          </geometry>
          <surface>
            <contact>
              <ode/>
            </contact>
            <friction>
              <ode/>
            </friction>
            <bounce/>
          </surface>
          <max_contacts>10</max_contacts>
        </collision>
        <collision name='base_link_collision_firefly/vi_sensor/camera_left_link'>
          <pose>0.115574 0.055 -0.02503 0 0.1 0</pose>
          <geometry>
            <cylinder>
              <length>0.01</length>
              <radius>0.007</radius>
            </cylinder>
          </geometry>
          <surface>
            <contact>
              <ode/>
            </contact>
            <friction>
              <ode/>
            </friction>
            <bounce/>
          </surface>
          <max_contacts>10</max_contacts>
        </collision>
        <collision name='base_link_collision_firefly/vi_sensor/camera_right_link'>
          <pose>0.115574 -0.055 -0.02503 0 0.1 0</pose>
          <geometry>
            <cylinder>
              <length>0.01</length>
              <radius>0.007</radius>
            </cylinder>
          </geometry>
          <max_contacts>10</max_contacts>
          <surface>
            <bounce/>
            <friction>
              <ode/>
            </friction>
            <contact>
              <ode/>
            </contact>
          </surface>
        </collision>
        <collision name='base_link_collision_firefly/vi_sensor/vi_sensor_link'>
          <pose>0.1 0 -0.03 0 0.1 0</pose>
          <geometry>
            <box>
              <size>0.03 0.133 0.057</size>
            </box>
          </geometry>
          <max_contacts>10</max_contacts>
          <surface>
            <bounce/>
            <friction>
              <ode/>
            </friction>
            <contact>
              <ode/>
            </contact>
          </surface>
        </collision>
        <visual name='base_link_visual_base_link_inertia'>
          <pose>0 0 0 0 -0 0</pose>
          <geometry>
            <mesh>
              <scale>1 1 1</scale>
              <uri>/home/daniel/catkin_ws/src/rotors_simulator/rotors_description/meshes/firefly.dae</uri>
            </mesh>
          </geometry>
        </visual>
        <visual name='base_link_visual_firefly/vi_sensor/vi_sensor_link'>
          <pose>0.1 0 -0.03 0 0.1 0</pose>
          <geometry>
            <mesh>
              <scale>1 1 1</scale>
              <uri>/home/daniel/catkin_ws/src/rotors_simulator/rotors_description/meshes/vi_sensor.dae</uri>
            </mesh>
          </geometry>
        </visual>
        <velocity_decay>
          <linear>0</linear>
          <angular>0</angular>
        </velocity_decay>
        <sensor name='firefly/vi_sensor_camera_{camera_suffix}' type='depth'>
          <always_on>1</always_on>
          <update_rate>30</update_rate>
          <camera name='__default__'>
            <horizontal_fov>2</horizontal_fov>
            <image>
              <format>L8</format>
              <width>640</width>
              <height>480</height>
            </image>
            <clip>
              <near>0.01</near>
              <far>100</far>
            </clip>
          </camera>
          <plugin name='firefly/vi_sensor_camera_{camera_suffix}' filename='libgazebo_ros_openni_kinect.so'>
            <robotNamespace>firefly/vi_sensor</robotNamespace>
            <alwaysOn>true</alwaysOn>
            <baseline>0.11</baseline>
            <updateRate>30.0</updateRate>
            <cameraName>camera_depth</cameraName>
            <imageTopicName>camera/image_raw</imageTopicName>
            <cameraInfoTopicName>camera/camera_info</cameraInfoTopicName>
            <depthImageTopicName>depth/disparity</depthImageTopicName>
            <depthImageCameraInfoTopicName>depth/camera_info</depthImageCameraInfoTopicName>
            <pointCloudTopicName>depth/points</pointCloudTopicName>
            <frameName>camera_depth_optical_center_link</frameName>
            <pointCloudCutoff>0.5</pointCloudCutoff>
            <distortionK1>0.0</distortionK1>
            <distortionK2>0.0</distortionK2>
            <distortionK3>0.0</distortionK3>
            <distortionT1>0.0</distortionT1>
            <distortionT2>0.0</distortionT2>
          </plugin>
          <pose>0.115574 0.055 -0.02503 0 0.1 0</pose>
        </sensor>
        <gravity>1</gravity>
        <velocity_decay>
          <linear>0</linear>
          <angular>0</angular>
        </velocity_decay>
        <self_collide>0</self_collide>
        <sensor name='firefly/vi_sensor_stereo_camera' type='multicamera'>
          <update_rate>30</update_rate>
          <camera name='left'>
            <pose>0 -0 0 0 -0 0</pose>
            <horizontal_fov>1.39626</horizontal_fov>
            <image>
              <width>752</width>
              <height>480</height>
              <format>L8</format>
            </image>
            <clip>
              <near>0.02</near>
              <far>30</far>
            </clip>
            <noise>
              <type>gaussian</type>
              <mean>0</mean>
              <stddev>0.007</stddev>
            </noise>
          </camera>
          <camera name='right'>
            <pose>0 -0.11 0 0 -0 0</pose>
            <horizontal_fov>1.39626</horizontal_fov>
            <image>
              <width>752</width>
              <height>480</height>
              <format>L8</format>
            </image>
            <clip>
              <near>0.02</near>
              <far>30</far>
            </clip>
            <noise>
              <type>gaussian</type>
              <mean>0</mean>
              <stddev>0.007</stddev>
            </noise>
          </camera>
          <plugin name='firefly/vi_sensor_stereo_camera_controller' filename='libgazebo_ros_multicamera.so'>
            <alwaysOn>true</alwaysOn>
            <updateRate>0.0</updateRate>
            <cameraName>vi_sensor</cameraName>
            <imageTopicName>image_raw</imageTopicName>
            <cameraInfoTopicName>camera_info</cameraInfoTopicName>
            <frameName>vi_sensor/camera_left_link</frameName>
            <hackBaseline>0.11</hackBaseline>
            <distortionK1>0.0</distortionK1>
            <distortionK2>0.0</distortionK2>
            <distortionK3>0.0</distortionK3>
            <distortionT1>0.0</distortionT1>
            <distortionT2>0.0</distortionT2>
            <robotNamespace>/firefly/</robotNamespace>
          </plugin>
          <pose>0.115574 0.055 -0.02503 0 0.1 0</pose>
        </sensor>
        <kinematic>0</kinematic>
      </link>
      <link name='firefly/ground_truth/odometry_sensorgt_link'>
        <pose>0 0 0 0 -0 0</pose>
        <inertial>
          <pose>0 0 0 0 -0 0</pose>
          <mass>1e-05</mass>
          <inertia>
            <ixx>1e-05</ixx>
            <ixy>0</ixy>
            <ixz>0</ixz>
            <iyy>1e-05</iyy>
            <iyz>0</iyz>
            <izz>1e-05</izz>
          </inertia>
        </inertial>
        <velocity_decay>
          <linear>0</linear>
          <angular>0</angular>
        </velocity_decay>
        <self_collide>0</self_collide>
        <kinematic>0</kinematic>
        <gravity>1</gravity>
      </link>
      <joint name='firefly/ground_truth/odometry_sensorgt_joint' type='revolute'>
        <child>firefly/ground_truth/odometry_sensorgt_link</child>
        <parent>base_link</parent>
        <axis>
          <xyz>1 0 0</xyz>
          <limit>
            <lower>0</lower>
            <upper>0</upper>
            <effort>0</effort>
            <velocity>0</velocity>
          </limit>
          <dynamics/>
        </axis>
      </joint>
      <link name='firefly/imu_link'>
        <pose>0 0 0 0 -0 0</pose>
        <inertial>
          <pose>0 0 0 0 -0 0</pose>
          <mass>0.015</mass>
          <inertia>
            <ixx>1e-05</ixx>
            <ixy>0</ixy>
            <ixz>0</ixz>
            <iyy>1e-05</iyy>
            <iyz>0</iyz>
            <izz>1e-05</izz>
          </inertia>
        </inertial>
        <velocity_decay>
          <linear>0</linear>
          <angular>0</angular>
        </velocity_decay>
        <self_collide>0</self_collide>
        <kinematic>0</kinematic>
        <gravity>1</gravity>
      </link>
      <joint name='firefly/imu_joint' type='revolute'>
        <child>firefly/imu_link</child>
        <parent>base_link</parent>
        <axis>
          <xyz>1 0 0</xyz>
          <limit>
            <lower>0</lower>
            <upper>0</upper>
            <effort>0</effort>
            <velocity>0</velocity>
          </limit>
          <dynamics/>
        </axis>
      </joint>
      <link name='firefly/imugt_link'>
        <pose>0 0 0 0 -0 0</pose>
        <inertial>
          <pose>0 0 0 0 -0 0</pose>
          <mass>1e-05</mass>
          <inertia>
            <ixx>1e-05</ixx>
            <ixy>0</ixy>
            <ixz>0</ixz>
            <iyy>1e-05</iyy>
            <iyz>0</iyz>
            <izz>1e-05</izz>
          </inertia>
        </inertial>
        <velocity_decay>
          <linear>0</linear>
          <angular>0</angular>
        </velocity_decay>
        <self_collide>0</self_collide>
        <kinematic>0</kinematic>
        <gravity>1</gravity>
      </link>
      <joint name='firefly/imugt_joint' type='revolute'>
        <child>firefly/imugt_link</child>
        <parent>base_link</parent>
        <axis>
          <xyz>1 0 0</xyz>
          <limit>
            <lower>0</lower>
            <upper>0</upper>
            <effort>0</effort>
            <velocity>0</velocity>
          </limit>
          <dynamics/>
        </axis>
      </joint>
      <link name='firefly/odometry_sensor1/odometry_sensor1_link'>
        <pose>0 0 0 0 -0 0</pose>
        <inertial>
          <pose>0 0 0 0 -0 0</pose>
          <mass>1e-05</mass>
          <inertia>
            <ixx>1e-05</ixx>
            <ixy>0</ixy>
            <ixz>0</ixz>
            <iyy>1e-05</iyy>
            <iyz>0</iyz>
            <izz>1e-05</izz>
          </inertia>
        </inertial>
        <velocity_decay>
          <linear>0</linear>
          <angular>0</angular>
        </velocity_decay>
        <self_collide>0</self_collide>
        <kinematic>0</kinematic>
        <gravity>1</gravity>
      </link>
      <joint name='firefly/odometry_sensor1/odometry_sensor1_joint' type='revolute'>
        <child>firefly/odometry_sensor1/odometry_sensor1_link</child>
        <parent>base_link</parent>
        <axis>
          <xyz>1 0 0</xyz>
          <limit>
            <lower>0</lower>
            <upper>0</upper>
            <effort>0</effort>
            <velocity>0</velocity>
          </limit>
          <dynamics/>
        </axis>
      </joint>
      <link name='rotor_0'>
        <pose>0.186195 0.1075 0.037 0 -0 0</pose>
        <inertial>
          <pose>0 0 0 0 -0 0</pose>
          <mass>0.005</mass>
          <inertia>
            <ixx>9.75e-07</ixx>
            <ixy>0</ixy>
            <ixz>0</ixz>
            <iyy>4.17041e-05</iyy>
            <iyz>0</iyz>
            <izz>4.26041e-05</izz>
          </inertia>
        </inertial>
        <collision name='rotor_0_collision'>
          <pose>0 0 0 0 -0 0</pose>
          <geometry>
            <cylinder>
              <length>0.005</length>
              <radius>0.1</radius>
            </cylinder>
          </geometry>
          <surface>
            <contact>
              <ode/>
            </contact>
            <friction>
              <ode/>
            </friction>
            <bounce/>
          </surface>
          <max_contacts>10</max_contacts>
        </collision>
        <visual name='rotor_0_visual'>
          <pose>0 0 0 0 -0 0</pose>
          <geometry>
            <mesh>
              <scale>0.1 0.1 0.1</scale>
              <uri>/home/daniel/catkin_ws/src/rotors_simulator/rotors_description/meshes/propeller_ccw.dae</uri>
            </mesh>
          </geometry>
          <material>
            <script>
              <name>Gazebo/Red</name>
              <uri>__default__</uri>
            </script>
          </material>
        </visual>
        <gravity>1</gravity>
        <velocity_decay>
          <linear>0</linear>
          <angular>0</angular>
        </velocity_decay>
        <self_collide>0</self_collide>
        <kinematic>0</kinematic>
      </link>
      <joint name='rotor_0_joint' type='revolute'>
        <child>rotor_0</child>
        <parent>base_link</parent>
        <axis>
          <xyz>0 0 1</xyz>
          <limit>
            <lower>-1e+16</lower>
            <upper>1e+16</upper>
          </limit>
          <dynamics/>
        </axis>
      </joint>
      <link name='rotor_1'>
        <pose>0 0.215 0.037 0 -0 0</pose>
        <inertial>
          <pose>0 0 0 0 -0 0</pose>
          <mass>0.005</mass>
          <inertia>
            <ixx>9.75e-07</ixx>
            <ixy>0</ixy>
            <ixz>0</ixz>
            <iyy>4.17041e-05</iyy>
            <iyz>0</iyz>
            <izz>4.26041e-05</izz>
          </inertia>
        </inertial>
        <collision name='rotor_1_collision'>
          <pose>0 0 0 0 -0 0</pose>
          <geometry>
            <cylinder>
              <length>0.005</length>
              <radius>0.1</radius>
            </cylinder>
          </geometry>
          <surface>
            <contact>
              <ode/>
            </contact>
            <friction>
              <ode/>
            </friction>
            <bounce/>
          </surface>
          <max_contacts>10</max_contacts>
        </collision>
        <visual name='rotor_1_visual'>
          <pose>0 0 0 0 -0 0</pose>
          <geometry>
            <mesh>
              <scale>0.1 0.1 0.1</scale>
              <uri>/home/daniel/catkin_ws/src/rotors_simulator/rotors_description/meshes/propeller_cw.dae</uri>
            </mesh>
          </geometry>
          <material>
            <script>
              <name>Gazebo/Blue</name>
              <uri>__default__</uri>
            </script>
          </material>
        </visual>
        <gravity>1</gravity>
        <velocity_decay>
          <linear>0</linear>
          <angular>0</angular>
        </velocity_decay>
        <self_collide>0</self_collide>
        <kinematic>0</kinematic>
      </link>
      <joint name='rotor_1_joint' type='revolute'>
        <child>rotor_1</child>
        <parent>base_link</parent>
        <axis>
          <xyz>0 0 1</xyz>
          <limit>
            <lower>-1e+16</lower>
            <upper>1e+16</upper>
          </limit>
          <dynamics/>
        </axis>
      </joint>
      <link name='rotor_2'>
        <pose>-0.186195 0.1075 0.037 0 -0 0</pose>
        <inertial>
          <pose>0 0 0 0 -0 0</pose>
          <mass>0.005</mass>
          <inertia>
            <ixx>9.75e-07</ixx>
            <ixy>0</ixy>
            <ixz>0</ixz>
            <iyy>4.17041e-05</iyy>
            <iyz>0</iyz>
            <izz>4.26041e-05</izz>
          </inertia>
        </inertial>
        <collision name='rotor_2_collision'>
          <pose>0 0 0 0 -0 0</pose>
          <geometry>
            <cylinder>
              <length>0.005</length>
              <radius>0.1</radius>
            </cylinder>
          </geometry>
          <surface>
            <contact>
              <ode/>
            </contact>
            <friction>
              <ode/>
            </friction>
            <bounce/>
          </surface>
          <max_contacts>10</max_contacts>
        </collision>
        <visual name='rotor_2_visual'>
          <pose>0 0 0 0 -0 0</pose>
          <geometry>
            <mesh>
              <scale>0.1 0.1 0.1</scale>
              <uri>/home/daniel/catkin_ws/src/rotors_simulator/rotors_description/meshes/propeller_ccw.dae</uri>
            </mesh>
          </geometry>
          <material>
            <script>
              <name>Gazebo/Blue</name>
              <uri>__default__</uri>
            </script>
          </material>
        </visual>
        <gravity>1</gravity>
        <velocity_decay>
          <linear>0</linear>
          <angular>0</angular>
        </velocity_decay>
        <self_collide>0</self_collide>
        <kinematic>0</kinematic>
      </link>
      <joint name='rotor_2_joint' type='revolute'>
        <child>rotor_2</child>
        <parent>base_link</parent>
        <axis>
          <xyz>0 0 1</xyz>
          <limit>
            <lower>-1e+16</lower>
            <upper>1e+16</upper>
          </limit>
          <dynamics/>
        </axis>
      </joint>
      <link name='rotor_3'>
        <pose>-0.186195 -0.1075 0.037 0 -0 0</pose>
        <inertial>
          <pose>0 0 0 0 -0 0</pose>
          <mass>0.005</mass>
          <inertia>
            <ixx>9.75e-07</ixx>
            <ixy>0</ixy>
            <ixz>0</ixz>
            <iyy>4.17041e-05</iyy>
            <iyz>0</iyz>
            <izz>4.26041e-05</izz>
          </inertia>
        </inertial>
        <collision name='rotor_3_collision'>
          <pose>0 0 0 0 -0 0</pose>
          <geometry>
            <cylinder>
              <length>0.005</length>
              <radius>0.1</radius>
            </cylinder>
          </geometry>
          <surface>
            <contact>
              <ode/>
            </contact>
            <friction>
              <ode/>
            </friction>
            <bounce/>
          </surface>
          <max_contacts>10</max_contacts>
        </collision>
        <visual name='rotor_3_visual'>
          <pose>0 0 0 0 -0 0</pose>
          <geometry>
            <mesh>
              <scale>0.1 0.1 0.1</scale>
              <uri>/home/daniel/catkin_ws/src/rotors_simulator/rotors_description/meshes/propeller_cw.dae</uri>
            </mesh>
          </geometry>
          <material>
            <script>
              <name>Gazebo/Blue</name>
              <uri>__default__</uri>
            </script>
          </material>
        </visual>
        <gravity>1</gravity>
        <velocity_decay>
          <linear>0</linear>
          <angular>0</angular>
        </velocity_decay>
        <self_collide>0</self_collide>
        <kinematic>0</kinematic>
      </link>
      <joint name='rotor_3_joint' type='revolute'>
        <child>rotor_3</child>
        <parent>base_link</parent>
        <axis>
          <xyz>0 0 1</xyz>
          <limit>
            <lower>-1e+16</lower>
            <upper>1e+16</upper>
          </limit>
          <dynamics/>
        </axis>
      </joint>
      <link name='rotor_4'>
        <pose>0 -0.215 0.037 0 -0 0</pose>
        <inertial>
          <pose>0 0 0 0 -0 0</pose>
          <mass>0.005</mass>
          <inertia>
            <ixx>9.75e-07</ixx>
            <ixy>0</ixy>
            <ixz>0</ixz>
            <iyy>4.17041e-05</iyy>
            <iyz>0</iyz>
            <izz>4.26041e-05</izz>
          </inertia>
        </inertial>
        <collision name='rotor_4_collision'>
          <pose>0 0 0 0 -0 0</pose>
          <geometry>
            <cylinder>
              <length>0.005</length>
              <radius>0.1</radius>
            </cylinder>
          </geometry>
          <surface>
            <contact>
              <ode/>
            </contact>
            <friction>
              <ode/>
            </friction>
            <bounce/>
          </surface>
          <max_contacts>10</max_contacts>
        </collision>
        <visual name='rotor_4_visual'>
          <pose>0 0 0 0 -0 0</pose>
          <geometry>
            <mesh>
              <scale>0.1 0.1 0.1</scale>
              <uri>/home/daniel/catkin_ws/src/rotors_simulator/rotors_description/meshes/propeller_ccw.dae</uri>
            </mesh>
          </geometry>
          <material>
            <script>
              <name>Gazebo/Blue</name>
              <uri>__default__</uri>
            </script>
          </material>
        </visual>
        <gravity>1</gravity>
        <velocity_decay>
          <linear>0</linear>
          <angular>0</angular>
        </velocity_decay>
        <self_collide>0</self_collide>
        <kinematic>0</kinematic>
      </link>
      <joint name='rotor_4_joint' type='revolute'>
        <child>rotor_4</child>
        <parent>base_link</parent>
        <axis>
          <xyz>0 0 1</xyz>
          <limit>
            <lower>-1e+16</lower>
            <upper>1e+16</upper>
          </limit>
          <dynamics/>
        </axis>
      </joint>
      <link name='rotor_5'>
        <pose>0.186195 -0.1075 0.037 0 -0 0</pose>
        <inertial>
          <pose>0 0 0 0 -0 0</pose>
          <mass>0.005</mass>
          <inertia>
            <ixx>9.75e-07</ixx>
            <ixy>0</ixy>
            <ixz>0</ixz>
            <iyy>4.17041e-05</iyy>
            <iyz>0</iyz>
            <izz>4.26041e-05</izz>
          </inertia>
        </inertial>
        <collision name='rotor_5_collision'>
          <pose>0 0 0 0 -0 0</pose>
          <geometry>
            <cylinder>
              <length>0.005</length>
              <radius>0.1</radius>
            </cylinder>
          </geometry>
          <surface>
            <contact>
              <ode/>
            </contact>
            <friction>
              <ode/>
            </friction>
            <bounce/>
          </surface>
          <max_contacts>10</max_contacts>
        </collision>
        <visual name='rotor_5_visual'>
          <pose>0 0 0 0 -0 0</pose>
          <geometry>
            <mesh>
              <scale>0.1 0.1 0.1</scale>
              <uri>/home/daniel/catkin_ws/src/rotors_simulator/rotors_description/meshes/propeller_cw.dae</uri>
            </mesh>
          </geometry>
          <material>
            <script>
              <name>Gazebo/Red</name>
              <uri>__default__</uri>
            </script>
          </material>
        </visual>
        <gravity>1</gravity>
        <velocity_decay>
          <linear>0</linear>
          <angular>0</angular>
        </velocity_decay>
        <self_collide>0</self_collide>
        <kinematic>0</kinematic>
      </link>
      <joint name='rotor_5_joint' type='revolute'>
        <child>rotor_5</child>
        <parent>base_link</parent>
        <axis>
          <xyz>0 0 1</xyz>
          <limit>
            <lower>-1e+16</lower>
            <upper>1e+16</upper>
          </limit>
          <dynamics/>
        </axis>
      </joint>
      <link name='firefly/vi_sensor/ground_truth/odometry_sensor_link'>
        <pose>0.1 0 -0.03 0 0.1 0</pose>
        <inertial>
          <pose>0 0 0 0 -0 0</pose>
          <mass>1e-05</mass>
          <inertia>
            <ixx>1e-05</ixx>
            <ixy>0</ixy>
            <ixz>0</ixz>
            <iyy>1e-05</iyy>
            <iyz>0</iyz>
            <izz>1e-05</izz>
          </inertia>
        </inertial>
        <velocity_decay>
          <linear>0</linear>
          <angular>0</angular>
        </velocity_decay>
        <self_collide>0</self_collide>
        <kinematic>0</kinematic>
        <gravity>1</gravity>
      </link>
      <joint name='firefly/vi_sensor/ground_truth/odometry_sensor_joint' type='revolute'>
        <child>firefly/vi_sensor/ground_truth/odometry_sensor_link</child>
        <parent>base_link</parent>
        <axis>
          <xyz>0.995004 0 -0.099833</xyz>
          <limit>
            <lower>0</lower>
            <upper>0</upper>
            <effort>0</effort>
            <velocity>0</velocity>
          </limit>
          <dynamics/>
        </axis>
      </joint>
      <link name='firefly/vi_sensor/imu_link'>
        <pose>0.116053 0 -0.020254 0 0.1 0</pose>
        <inertial>
          <pose>0 0 0 0 -0 0</pose>
          <mass>0.015</mass>
          <inertia>
            <ixx>1e-05</ixx>
            <ixy>0</ixy>
            <ixz>0</ixz>
            <iyy>1e-05</iyy>
            <iyz>0</iyz>
            <izz>1e-05</izz>
          </inertia>
        </inertial>
        <velocity_decay>
          <linear>0</linear>
          <angular>0</angular>
        </velocity_decay>
        <self_collide>0</self_collide>
        <kinematic>0</kinematic>
        <gravity>1</gravity>
      </link>
      <joint name='firefly/vi_sensor/imu_joint' type='revolute'>
        <child>firefly/vi_sensor/imu_link</child>
        <parent>base_link</parent>
        <axis>
          <xyz>0.995004 0 -0.099833</xyz>
          <limit>
            <lower>0</lower>
            <upper>0</upper>
            <effort>0</effort>
            <velocity>0</velocity>
          </limit>
          <dynamics/>
        </axis>
      </joint>
      <plugin name='rosbag' filename='librotors_gazebo_multirotor_base_plugin.so'>
        <robotNamespace>firefly</robotNamespace>
        <linkName>base_link</linkName>
        <rotorVelocitySlowdownSim>10</rotorVelocitySlowdownSim>
      </plugin>
      <plugin name='front_left_motor_model' filename='librotors_gazebo_motor_model.so'>
        <robotNamespace>firefly</robotNamespace>
        <jointName>rotor_0_joint</jointName>
        <linkName>rotor_0</linkName>
        <turningDirection>ccw</turningDirection>
        <timeConstantUp>0.0125</timeConstantUp>
        <timeConstantDown>0.025</timeConstantDown>
        <maxRotVelocity>838</maxRotVelocity>
        <motorConstant>8.54858e-06</motorConstant>
        <momentConstant>0.016</momentConstant>
        <commandSubTopic>gazebo/command/motor_speed</commandSubTopic>
        <motorNumber>0</motorNumber>
        <rotorDragCoefficient>8.06428e-05</rotorDragCoefficient>
        <rollingMomentCoefficient>1e-06</rollingMomentCoefficient>
        <motorSpeedPubTopic>motor_speed/0</motorSpeedPubTopic>
        <rotorVelocitySlowdownSim>10</rotorVelocitySlowdownSim>
      </plugin>
      <plugin name='left_motor_model' filename='librotors_gazebo_motor_model.so'>
        <robotNamespace>firefly</robotNamespace>
        <jointName>rotor_1_joint</jointName>
        <linkName>rotor_1</linkName>
        <turningDirection>cw</turningDirection>
        <timeConstantUp>0.0125</timeConstantUp>
        <timeConstantDown>0.025</timeConstantDown>
        <maxRotVelocity>838</maxRotVelocity>
        <motorConstant>8.54858e-06</motorConstant>
        <momentConstant>0.016</momentConstant>
        <commandSubTopic>gazebo/command/motor_speed</commandSubTopic>
        <motorNumber>1</motorNumber>
        <rotorDragCoefficient>8.06428e-05</rotorDragCoefficient>
        <rollingMomentCoefficient>1e-06</rollingMomentCoefficient>
        <motorSpeedPubTopic>motor_speed/1</motorSpeedPubTopic>
        <rotorVelocitySlowdownSim>10</rotorVelocitySlowdownSim>
      </plugin>
      <plugin name='back_left_motor_model' filename='librotors_gazebo_motor_model.so'>
        <robotNamespace>firefly</robotNamespace>
        <jointName>rotor_2_joint</jointName>
        <linkName>rotor_2</linkName>
        <turningDirection>ccw</turningDirection>
        <timeConstantUp>0.0125</timeConstantUp>
        <timeConstantDown>0.025</timeConstantDown>
        <maxRotVelocity>838</maxRotVelocity>
        <motorConstant>8.54858e-06</motorConstant>
        <momentConstant>0.016</momentConstant>
        <commandSubTopic>gazebo/command/motor_speed</commandSubTopic>
        <motorNumber>2</motorNumber>
        <rotorDragCoefficient>8.06428e-05</rotorDragCoefficient>
        <rollingMomentCoefficient>1e-06</rollingMomentCoefficient>
        <motorSpeedPubTopic>motor_speed/2</motorSpeedPubTopic>
        <rotorVelocitySlowdownSim>10</rotorVelocitySlowdownSim>
      </plugin>
      <plugin name='back_right_motor_model' filename='librotors_gazebo_motor_model.so'>
        <robotNamespace>firefly</robotNamespace>
        <jointName>rotor_3_joint</jointName>
        <linkName>rotor_3</linkName>
        <turningDirection>cw</turningDirection>
        <timeConstantUp>0.0125</timeConstantUp>
        <timeConstantDown>0.025</timeConstantDown>
        <maxRotVelocity>838</maxRotVelocity>
        <motorConstant>8.54858e-06</motorConstant>
        <momentConstant>0.016</momentConstant>
        <commandSubTopic>gazebo/command/motor_speed</commandSubTopic>
        <motorNumber>3</motorNumber>
        <rotorDragCoefficient>8.06428e-05</rotorDragCoefficient>
        <rollingMomentCoefficient>1e-06</rollingMomentCoefficient>
        <motorSpeedPubTopic>motor_speed/3</motorSpeedPubTopic>
        <rotorVelocitySlowdownSim>10</rotorVelocitySlowdownSim>
      </plugin>
      <plugin name='right_motor_model' filename='librotors_gazebo_motor_model.so'>
        <robotNamespace>firefly</robotNamespace>
        <jointName>rotor_4_joint</jointName>
        <linkName>rotor_4</linkName>
        <turningDirection>ccw</turningDirection>
        <timeConstantUp>0.0125</timeConstantUp>
        <timeConstantDown>0.025</timeConstantDown>
        <maxRotVelocity>838</maxRotVelocity>
        <motorConstant>8.54858e-06</motorConstant>
        <momentConstant>0.016</momentConstant>
        <commandSubTopic>gazebo/command/motor_speed</commandSubTopic>
        <motorNumber>4</motorNumber>
        <rotorDragCoefficient>8.06428e-05</rotorDragCoefficient>
        <rollingMomentCoefficient>1e-06</rollingMomentCoefficient>
        <motorSpeedPubTopic>motor_speed/4</motorSpeedPubTopic>
        <rotorVelocitySlowdownSim>10</rotorVelocitySlowdownSim>
      </plugin>
      <plugin name='front_right_motor_model' filename='librotors_gazebo_motor_model.so'>
        <robotNamespace>firefly</robotNamespace>
        <jointName>rotor_5_joint</jointName>
        <linkName>rotor_5</linkName>
        <turningDirection>cw</turningDirection>
        <timeConstantUp>0.0125</timeConstantUp>
        <timeConstantDown>0.025</timeConstantDown>
        <maxRotVelocity>838</maxRotVelocity>
        <motorConstant>8.54858e-06</motorConstant>
        <momentConstant>0.016</momentConstant>
        <commandSubTopic>gazebo/command/motor_speed</commandSubTopic>
        <motorNumber>5</motorNumber>
        <rotorDragCoefficient>8.06428e-05</rotorDragCoefficient>
        <rollingMomentCoefficient>1e-06</rollingMomentCoefficient>
        <motorSpeedPubTopic>motor_speed/5</motorSpeedPubTopic>
        <rotorVelocitySlowdownSim>10</rotorVelocitySlowdownSim>
      </plugin>
      <plugin name='controller_interface' filename='librotors_gazebo_controller_interface.so'>
        <robotNamespace>firefly</robotNamespace>
        <commandAttitudeThrustSubTopic>command/attitude</commandAttitudeThrustSubTopic>
        <commandRateThrustSubTopic>command/rate</commandRateThrustSubTopic>
        <commandMotorSpeedSubTopic>command/motor_speed</commandMotorSpeedSubTopic>
        <imuSubTopic>imu</imuSubTopic>
        <motorSpeedCommandPubTopic>gazebo/command/motor_speed</motorSpeedCommandPubTopic>
      </plugin>
      <plugin name='rotors_gazebo_imu_plugin' filename='librotors_gazebo_imu_plugin.so'>
        <robotNamespace>firefly</robotNamespace>
        <linkName>firefly/imu_link</linkName>
        <imuTopic>imu</imuTopic>
        <gyroscopeNoiseDensity>0.0003394</gyroscopeNoiseDensity>
        <gyroscopeRandomWalk>3.8785e-05</gyroscopeRandomWalk>
        <gyroscopeBiasCorrelationTime>1000.0</gyroscopeBiasCorrelationTime>
        <gyroscopeTurnOnBiasSigma>0.0087</gyroscopeTurnOnBiasSigma>
        <accelerometerNoiseDensity>0.004</accelerometerNoiseDensity>
        <accelerometerRandomWalk>0.006</accelerometerRandomWalk>
        <accelerometerBiasCorrelationTime>300.0</accelerometerBiasCorrelationTime>
        <accelerometerTurnOnBiasSigma>0.196</accelerometerTurnOnBiasSigma>
      </plugin>
      <plugin name='rotors_gazebo_imugt_plugin' filename='librotors_gazebo_imu_plugin.so'>
        <robotNamespace>firefly</robotNamespace>
        <linkName>firefly/imugt_link</linkName>
        <imuTopic>ground_truth/imu</imuTopic>
        <gyroscopeNoiseDensity>0.0</gyroscopeNoiseDensity>
        <gyroscopeRandomWalk>0.0</gyroscopeRandomWalk>
        <gyroscopeBiasCorrelationTime>1000.0</gyroscopeBiasCorrelationTime>
        <gyroscopeTurnOnBiasSigma>0.0</gyroscopeTurnOnBiasSigma>
        <accelerometerNoiseDensity>0.0</accelerometerNoiseDensity>
        <accelerometerRandomWalk>0.0</accelerometerRandomWalk>
        <accelerometerBiasCorrelationTime>300.0</accelerometerBiasCorrelationTime>
        <accelerometerTurnOnBiasSigma>0.0</accelerometerTurnOnBiasSigma>
      </plugin>
      <plugin name='odometry_sensorgt' filename='librotors_gazebo_odometry_plugin.so'>
        <linkName>firefly/ground_truth/odometry_sensorgt_link</linkName>
        <robotNamespace>firefly/ground_truth</robotNamespace>
        <poseTopic>pose</poseTopic>
        <poseWithCovarianceTopic>pose_with_covariance</poseWithCovarianceTopic>
        <positionTopic>position</positionTopic>
        <transformTopic>transform</transformTopic>
        <odometryTopic>odometry</odometryTopic>
        <parentFrameId>world</parentFrameId>
        <measurementDivisor>1</measurementDivisor>
        <measurementDelay>0</measurementDelay>
        <unknownDelay>0.0</unknownDelay>
        <noiseNormalPosition>0 0 0</noiseNormalPosition>
        <noiseNormalQuaternion>0 0 0</noiseNormalQuaternion>
        <noiseNormalLinearVelocity>0 0 0</noiseNormalLinearVelocity>
        <noiseNormalAngularVelocity>0 0 0</noiseNormalAngularVelocity>
        <noiseUniformPosition>0 0 0</noiseUniformPosition>
        <noiseUniformQuaternion>0 0 0</noiseUniformQuaternion>
        <noiseUniformLinearVelocity>0 0 0</noiseUniformLinearVelocity>
        <noiseUniformAngularVelocity>0 0 0</noiseUniformAngularVelocity>
      </plugin>
      <plugin name='odometry_sensor1' filename='librotors_gazebo_odometry_plugin.so'>
        <linkName>firefly/odometry_sensor1/odometry_sensor1_link</linkName>
        <robotNamespace>firefly/odometry_sensor1</robotNamespace>
        <poseTopic>pose</poseTopic>
        <poseWithCovarianceTopic>pose_with_covariance</poseWithCovarianceTopic>
        <positionTopic>position</positionTopic>
        <transformTopic>transform</transformTopic>
        <odometryTopic>odometry</odometryTopic>
        <parentFrameId>world</parentFrameId>
        <measurementDivisor>1</measurementDivisor>
        <measurementDelay>0</measurementDelay>
        <unknownDelay>0.0</unknownDelay>
        <noiseNormalPosition>0 0 0</noiseNormalPosition>
        <noiseNormalQuaternion>0 0 0</noiseNormalQuaternion>
        <noiseNormalLinearVelocity>0 0 0</noiseNormalLinearVelocity>
        <noiseNormalAngularVelocity>0 0 0</noiseNormalAngularVelocity>
        <noiseUniformPosition>0.1 0.1 0.1</noiseUniformPosition>
        <noiseUniformQuaternion>0 0 0</noiseUniformQuaternion>
        <noiseUniformLinearVelocity>0 0 0</noiseUniformLinearVelocity>
        <noiseUniformAngularVelocity>0 0 0</noiseUniformAngularVelocity>
      </plugin>
      <plugin name='odometry_sensor' filename='librotors_gazebo_odometry_plugin.so'>
        <linkName>firefly/vi_sensor/ground_truth/odometry_sensor_link</linkName>
        <robotNamespace>firefly/vi_sensor/ground_truth</robotNamespace>
        <poseTopic>pose</poseTopic>
        <poseWithCovarianceTopic>pose_with_covariance</poseWithCovarianceTopic>
        <positionTopic>position</positionTopic>
        <transformTopic>transform</transformTopic>
        <odometryTopic>odometry</odometryTopic>
        <parentFrameId>world</parentFrameId>
        <measurementDivisor>1</measurementDivisor>
        <measurementDelay>0</measurementDelay>
        <unknownDelay>0.0</unknownDelay>
        <noiseNormalPosition>0 0 0</noiseNormalPosition>
        <noiseNormalQuaternion>0 0 0</noiseNormalQuaternion>
        <noiseNormalLinearVelocity>0 0 0</noiseNormalLinearVelocity>
        <noiseNormalAngularVelocity>0 0 0</noiseNormalAngularVelocity>
        <noiseUniformPosition>0 0 0</noiseUniformPosition>
        <noiseUniformQuaternion>0 0 0</noiseUniformQuaternion>
        <noiseUniformLinearVelocity>0 0 0</noiseUniformLinearVelocity>
        <noiseUniformAngularVelocity>0 0 0</noiseUniformAngularVelocity>
      </plugin>
      <static>0</static>
      <plugin name='rotors_gazebo_imu_plugin' filename='librotors_gazebo_imu_plugin.so'>
        <robotNamespace>firefly/vi_sensor</robotNamespace>
        <linkName>firefly/vi_sensor/imu_link</linkName>
        <imuTopic>imu</imuTopic>
        <gyroscopeNoiseDensity>0.0003394</gyroscopeNoiseDensity>
        <gyroscopeRandomWalk>3.8785e-05</gyroscopeRandomWalk>
        <gyroscopeBiasCorrelationTime>1000.0</gyroscopeBiasCorrelationTime>
        <gyroscopeTurnOnBiasSigma>0.0087</gyroscopeTurnOnBiasSigma>
        <accelerometerNoiseDensity>0.004</accelerometerNoiseDensity>
        <accelerometerRandomWalk>0.006</accelerometerRandomWalk>
        <accelerometerBiasCorrelationTime>300.0</accelerometerBiasCorrelationTime>
        <accelerometerTurnOnBiasSigma>0.196</accelerometerTurnOnBiasSigma>
      </plugin>
      <pose>0 0 0.1 0 -0 0</pose>
    </model>
    <model name='RoboCup 3D Simulation Field_3'>
      <static>1</static>
      <link name='field'>
        <pose>0 0 0.01 0 -0 0</pose>
        <collision name='collision'>
          <geometry>
            <plane>
              <normal>0 0 1</normal>
              <size>30 20</size>
            </plane>
          </geometry>
          <surface>
            <friction>
              <ode>
                <mu>100</mu>
                <mu2>50</mu2>
              </ode>
            </friction>
            <bounce/>
            <contact>
              <ode/>
            </contact>
          </surface>
          <max_contacts>10</max_contacts>
        </collision>
        <visual name='base1'>
          <pose>0 11 0.001 0 -0 0</pose>
          <cast_shadows>0</cast_shadows>
          <geometry>
            <plane>
              <normal>0 0 1</normal>
              <size>34 2</size>
            </plane>
          </geometry>
          <material>
            <script>
              <uri>model://robocup_3Dsim_field/materials/scripts/</uri>
              <uri>model://robocup_3Dsim_field/materials/textures/</uri>
              <name>RoboCup/FieldBorder</name>
            </script>
          </material>
        </visual>
        <visual name='base2'>
          <pose>0 -11 0.001 0 -0 0</pose>
          <cast_shadows>0</cast_shadows>
          <geometry>
            <plane>
              <normal>0 0 1</normal>
              <size>34 2</size>
            </plane>
          </geometry>
          <material>
            <script>
              <uri>model://robocup_3Dsim_field/materials/scripts/</uri>
              <uri>model://robocup_3Dsim_field/materials/textures/</uri>
              <name>RoboCup/FieldBorder</name>
            </script>
          </material>
        </visual>
        <visual name='base3'>
          <pose>16 0 0.001 0 -0 0</pose>
          <cast_shadows>0</cast_shadows>
          <geometry>
            <plane>
              <normal>0 0 1</normal>
              <size>2 20</size>
            </plane>
          </geometry>
          <material>
            <script>
              <uri>model://robocup_3Dsim_field/materials/scripts/</uri>
              <uri>model://robocup_3Dsim_field/materials/textures/</uri>
              <name>RoboCup/FieldBorder</name>
            </script>
          </material>
        </visual>
        <visual name='base4'>
          <pose>-16 0 0.001 0 -0 0</pose>
          <cast_shadows>0</cast_shadows>
          <geometry>
            <plane>
              <normal>0 0 1</normal>
              <size>2 20</size>
            </plane>
          </geometry>
          <material>
            <script>
              <uri>model://robocup_3Dsim_field/materials/scripts/</uri>
              <uri>model://robocup_3Dsim_field/materials/textures/</uri>
              <name>RoboCup/FieldBorder</name>
            </script>
          </material>
        </visual>
        <visual name='carpet'>
          <cast_shadows>0</cast_shadows>
          <geometry>
            <plane>
              <normal>0 0 1</normal>
              <size>30 20</size>
            </plane>
          </geometry>
          <material>
            <script>
              <uri>model://robocup_3Dsim_field/materials/scripts/</uri>
              <uri>model://robocup_3Dsim_field/materials/textures/</uri>
              <name>RoboCup/Grass</name>
            </script>
          </material>
        </visual>
        <velocity_decay>
          <linear>0</linear>
          <angular>0</angular>
        </velocity_decay>
        <self_collide>0</self_collide>
        <kinematic>0</kinematic>
        <gravity>1</gravity>
      </link>
      <pose>-6 7 0 0 -0 0</pose>
    </model>
    <model name='RoboCup 3D Simulation Field_4'>
      <static>1</static>
      <link name='field'>
        <pose>0 0 0.01 0 -0 0</pose>
        <collision name='collision'>
          <geometry>
            <plane>
              <normal>0 0 1</normal>
              <size>30 20</size>
            </plane>
          </geometry>
          <surface>
            <friction>
              <ode>
                <mu>100</mu>
                <mu2>50</mu2>
              </ode>
            </friction>
            <bounce/>
            <contact>
              <ode/>
            </contact>
          </surface>
          <max_contacts>10</max_contacts>
        </collision>
        <visual name='base1'>
          <pose>0 11 0.001 0 -0 0</pose>
          <cast_shadows>0</cast_shadows>
          <geometry>
            <plane>
              <normal>0 0 1</normal>
              <size>34 2</size>
            </plane>
          </geometry>
          <material>
            <script>
              <uri>model://robocup_3Dsim_field/materials/scripts/</uri>
              <uri>model://robocup_3Dsim_field/materials/textures/</uri>
              <name>RoboCup/FieldBorder</name>
            </script>
          </material>
        </visual>
        <visual name='base2'>
          <pose>0 -11 0.001 0 -0 0</pose>
          <cast_shadows>0</cast_shadows>
          <geometry>
            <plane>
              <normal>0 0 1</normal>
              <size>34 2</size>
            </plane>
          </geometry>
          <material>
            <script>
              <uri>model://robocup_3Dsim_field/materials/scripts/</uri>
              <uri>model://robocup_3Dsim_field/materials/textures/</uri>
              <name>RoboCup/FieldBorder</name>
            </script>
          </material>
        </visual>
        <visual name='base3'>
          <pose>16 0 0.001 0 -0 0</pose>
          <cast_shadows>0</cast_shadows>
          <geometry>
            <plane>
              <normal>0 0 1</normal>
              <size>2 20</size>
            </plane>
          </geometry>
          <material>
            <script>
              <uri>model://robocup_3Dsim_field/materials/scripts/</uri>
              <uri>model://robocup_3Dsim_field/materials/textures/</uri>
              <name>RoboCup/FieldBorder</name>
            </script>
          </material>
        </visual>
        <visual name='base4'>
          <pose>-16 0 0.001 0 -0 0</pose>
          <cast_shadows>0</cast_shadows>
          <geometry>
            <plane>
              <normal>0 0 1</normal>
              <size>2 20</size>
            </plane>
          </geometry>
          <material>
            <script>
              <uri>model://robocup_3Dsim_field/materials/scripts/</uri>
              <uri>model://robocup_3Dsim_field/materials/textures/</uri>
              <name>RoboCup/FieldBorder</name>
            </script>
          </material>
        </visual>
        <visual name='carpet'>
          <cast_shadows>0</cast_shadows>
          <geometry>
            <plane>
              <normal>0 0 1</normal>
              <size>30 20</size>
            </plane>
          </geometry>
          <material>
            <script>
              <uri>model://robocup_3Dsim_field/materials/scripts/</uri>
              <uri>model://robocup_3Dsim_field/materials/textures/</uri>
              <name>RoboCup/Grass</name>
            </script>
          </material>
        </visual>
        <velocity_decay>
          <linear>0</linear>
          <angular>0</angular>
        </velocity_decay>
        <self_collide>0</self_collide>
        <kinematic>0</kinematic>
        <gravity>1</gravity>
      </link>
      <pose>25 7 0 0 -0 0</pose>
    </model>
    <model name='RoboCup 3D Simulation Field_5'>
      <static>1</static>
      <link name='field'>
        <pose>0 0 0.01 0 -0 0</pose>
        <collision name='collision'>
          <geometry>
            <plane>
              <normal>0 0 1</normal>
              <size>30 20</size>
            </plane>
          </geometry>
          <surface>
            <friction>
              <ode>
                <mu>100</mu>
                <mu2>50</mu2>
              </ode>
            </friction>
            <bounce/>
            <contact>
              <ode/>
            </contact>
          </surface>
          <max_contacts>10</max_contacts>
        </collision>
        <visual name='base1'>
          <pose>0 11 0.001 0 -0 0</pose>
          <cast_shadows>0</cast_shadows>
          <geometry>
            <plane>
              <normal>0 0 1</normal>
              <size>34 2</size>
            </plane>
          </geometry>
          <material>
            <script>
              <uri>model://robocup_3Dsim_field/materials/scripts/</uri>
              <uri>model://robocup_3Dsim_field/materials/textures/</uri>
              <name>RoboCup/FieldBorder</name>
            </script>
          </material>
        </visual>
        <visual name='base2'>
          <pose>0 -11 0.001 0 -0 0</pose>
          <cast_shadows>0</cast_shadows>
          <geometry>
            <plane>
              <normal>0 0 1</normal>
              <size>34 2</size>
            </plane>
          </geometry>
          <material>
            <script>
              <uri>model://robocup_3Dsim_field/materials/scripts/</uri>
              <uri>model://robocup_3Dsim_field/materials/textures/</uri>
              <name>RoboCup/FieldBorder</name>
            </script>
          </material>
        </visual>
        <visual name='base3'>
          <pose>16 0 0.001 0 -0 0</pose>
          <cast_shadows>0</cast_shadows>
          <geometry>
            <plane>
              <normal>0 0 1</normal>
              <size>2 20</size>
            </plane>
          </geometry>
          <material>
            <script>
              <uri>model://robocup_3Dsim_field/materials/scripts/</uri>
              <uri>model://robocup_3Dsim_field/materials/textures/</uri>
              <name>RoboCup/FieldBorder</name>
            </script>
          </material>
        </visual>
        <visual name='base4'>
          <pose>-16 0 0.001 0 -0 0</pose>
          <cast_shadows>0</cast_shadows>
          <geometry>
            <plane>
              <normal>0 0 1</normal>
              <size>2 20</size>
            </plane>
          </geometry>
          <material>
            <script>
              <uri>model://robocup_3Dsim_field/materials/scripts/</uri>
              <uri>model://robocup_3Dsim_field/materials/textures/</uri>
              <name>RoboCup/FieldBorder</name>
            </script>
          </material>
        </visual>
        <visual name='carpet'>
          <cast_shadows>0</cast_shadows>
          <geometry>
            <plane>
              <normal>0 0 1</normal>
              <size>30 20</size>
            </plane>
          </geometry>
          <material>
            <script>
              <uri>model://robocup_3Dsim_field/materials/scripts/</uri>
              <uri>model://robocup_3Dsim_field/materials/textures/</uri>
              <name>RoboCup/Grass</name>
            </script>
          </material>
        </visual>
        <velocity_decay>
          <linear>0</linear>
          <angular>0</angular>
        </velocity_decay>
        <self_collide>0</self_collide>
        <kinematic>0</kinematic>
        <gravity>1</gravity>
      </link>
      <pose>25 -15 0 0 -0 0</pose>
    </model>
    <model name='RoboCup 3D Simulation Field_6'>
      <static>1</static>
      <link name='field'>
        <pose>0 0 0.01 0 -0 0</pose>
        <collision name='collision'>
          <geometry>
            <plane>
              <normal>0 0 1</normal>
              <size>30 20</size>
            </plane>
          </geometry>
          <surface>
            <friction>
              <ode>
                <mu>100</mu>
                <mu2>50</mu2>
              </ode>
            </friction>
            <bounce/>
            <contact>
              <ode/>
            </contact>
          </surface>
          <max_contacts>10</max_contacts>
        </collision>
        <visual name='base1'>
          <pose>0 11 0.001 0 -0 0</pose>
          <cast_shadows>0</cast_shadows>
          <geometry>
            <plane>
              <normal>0 0 1</normal>
              <size>34 2</size>
            </plane>
          </geometry>
          <material>
            <script>
              <uri>model://robocup_3Dsim_field/materials/scripts/</uri>
              <uri>model://robocup_3Dsim_field/materials/textures/</uri>
              <name>RoboCup/FieldBorder</name>
            </script>
          </material>
        </visual>
        <visual name='base2'>
          <pose>0 -11 0.001 0 -0 0</pose>
          <cast_shadows>0</cast_shadows>
          <geometry>
            <plane>
              <normal>0 0 1</normal>
              <size>34 2</size>
            </plane>
          </geometry>
          <material>
            <script>
              <uri>model://robocup_3Dsim_field/materials/scripts/</uri>
              <uri>model://robocup_3Dsim_field/materials/textures/</uri>
              <name>RoboCup/FieldBorder</name>
            </script>
          </material>
        </visual>
        <visual name='base3'>
          <pose>16 0 0.001 0 -0 0</pose>
          <cast_shadows>0</cast_shadows>
          <geometry>
            <plane>
              <normal>0 0 1</normal>
              <size>2 20</size>
            </plane>
          </geometry>
          <material>
            <script>
              <uri>model://robocup_3Dsim_field/materials/scripts/</uri>
              <uri>model://robocup_3Dsim_field/materials/textures/</uri>
              <name>RoboCup/FieldBorder</name>
            </script>
          </material>
        </visual>
        <visual name='base4'>
          <pose>-16 0 0.001 0 -0 0</pose>
          <cast_shadows>0</cast_shadows>
          <geometry>
            <plane>
              <normal>0 0 1</normal>
              <size>2 20</size>
            </plane>
          </geometry>
          <material>
            <script>
              <uri>model://robocup_3Dsim_field/materials/scripts/</uri>
              <uri>model://robocup_3Dsim_field/materials/textures/</uri>
              <name>RoboCup/FieldBorder</name>
            </script>
          </material>
        </visual>
        <visual name='carpet'>
          <cast_shadows>0</cast_shadows>
          <geometry>
            <plane>
              <normal>0 0 1</normal>
              <size>30 20</size>
            </plane>
          </geometry>
          <material>
            <script>
              <uri>model://robocup_3Dsim_field/materials/scripts/</uri>
              <uri>model://robocup_3Dsim_field/materials/textures/</uri>
              <name>RoboCup/Grass</name>
            </script>
          </material>
        </visual>
        <velocity_decay>
          <linear>0</linear>
          <angular>0</angular>
        </velocity_decay>
        <self_collide>0</self_collide>
        <kinematic>0</kinematic>
        <gravity>1</gravity>
      </link>
      <pose>-6 -15 0 0 -0 0</pose>
    </model>
    <model name='BuildingDefaultName'>
      <static>1</static>
      <link name='__default__'>
        <velocity_decay>
          <linear>0</linear>
          <angular>0</angular>
        </velocity_decay>
        <self_collide>0</self_collide>
        <kinematic>0</kinematic>
        <gravity>1</gravity>
      </link>
    </model>
  </world>
</sdf>
