<sdf version='1.5'>
  <model name='plane'>
    <pose>0 0 0.246 0 0 0</pose>
    <link name='base_link'>
      <pose>0 0 0 0 0 0</pose>
      <inertial>
        <pose>0 0 0 0 0 0</pose>
        <mass>1.5</mass>
        <inertia>
          <ixx>0.197563</ixx>
          <ixy>0</ixy>
          <ixz>0</ixz>
          <iyy>0.1458929</iyy>
          <iyz>0</iyz>
          <izz>0.1477</izz>
        </inertia>
      </inertial>
      <collision name='base_link_collision'>
        <pose>0 0 -0.07 0 0 0</pose>
        <geometry>
          <box>
            <size>0.47 0.47 0.11</size>
          </box>
        </geometry>
        <surface>
          <contact>
            <ode>
              <max_vel>10</max_vel>
              <min_depth>0.01</min_depth>
            </ode>
          </contact>
          <!--<friction>
            <ode/>
          </friction>-->
        </surface>
      </collision>
      <visual name='base_link_visual'>
        <pose>0.07 0 -0.08 0 0 0</pose>
        <geometry>
          <mesh>
            <scale>0.1 0.1 0.1</scale>
            <uri>model://plane/meshes/body.dae</uri>
          </mesh>
        </geometry>
        <material>
          <script>
            <name>Gazebo/DarkGrey</name>
            <uri>__default__</uri>
          </script>
        </material>
      </visual>
      <gravity>1</gravity>
      <velocity_decay/>
      <self_collide>0</self_collide>
    </link>
    <link name='plane/imu_link'>
      <pose>0 0 0 0 0 0</pose>
      <inertial>
        <pose>0 0 0 0 0 0</pose>
        <mass>0.015</mass>
        <inertia>
          <ixx>1e-05</ixx>
          <ixy>0</ixy>
          <ixz>0</ixz>
          <iyy>1e-05</iyy>
          <iyz>0</iyz>
          <izz>1e-05</izz>
        </inertia>
      </inertial>
    </link>
    <joint name='plane/imu_joint' type='revolute'>
      <child>plane/imu_link</child>
      <parent>base_link</parent>
      <axis>
        <xyz>1 0 0</xyz>
        <limit>
          <lower>0</lower>
          <upper>0</upper>
          <effort>0</effort>
          <velocity>0</velocity>
        </limit>
        <dynamics>
          <spring_reference>0</spring_reference>
          <spring_stiffness>0</spring_stiffness>
        </dynamics>
        <use_parent_model_frame>1</use_parent_model_frame>
      </axis>
    </joint>
    <link name='rotor_puller'>
      <pose>0.3 0 0.0 0 1.57 0</pose>
      <inertial>
        <pose>0 0 0 0 0 0</pose>
        <mass>0.005</mass>
        <inertia>
          <ixx>9.75e-07</ixx>
          <ixy>0</ixy>
          <ixz>0</ixz>
          <iyy>0.000166704</iyy>
          <iyz>0</iyz>
          <izz>0.000167604</izz>
        </inertia>
      </inertial>
      <collision name='rotor_puller_collision'>
        <pose>0.0 0 0.0 0 0 0</pose>
        <geometry>
          <cylinder>
            <length>0.005</length>
            <radius>0.1</radius>
          </cylinder>
        </geometry>
        <surface>
          <contact>
            <ode/>
          </contact>
          <friction>
            <ode/>
          </friction>
        </surface>
      </collision>
      <visual name='rotor_puller_visual'>
        <pose>0 0 -0.09 0 0 0</pose>
        <geometry>
          <mesh>
            <scale>1 1 1</scale>
            <uri>model://plane/meshes/iris_prop_ccw.dae</uri>
          </mesh>
        </geometry>
        <material>
          <script>
            <name>Gazebo/Blue</name>
            <uri>__default__</uri>
          </script>
        </material>
      </visual>
      <gravity>1</gravity>
      <velocity_decay/>
      <self_collide>0</self_collide>
    </link>
    <joint name='rotor_puller_joint' type='revolute'>
      <child>rotor_puller</child>
      <parent>base_link</parent>
      <axis>
        <xyz>1 0 0</xyz>
        <limit>
          <lower>-1e+16</lower>
          <upper>1e+16</upper>
        </limit>
        <dynamics>
          <spring_reference>0</spring_reference>
          <spring_stiffness>0</spring_stiffness>
        </dynamics>
        <use_parent_model_frame>1</use_parent_model_frame>
      </axis>
    </joint>

    <link name="left_elevon">
      <inertial>
        <mass>0.00000001</mass>
        <inertia>
          <ixx>0.000001</ixx>
          <ixy>0.0</ixy>
          <iyy>0.000001</iyy>
          <ixz>0.0</ixz>
          <iyz>0.0</iyz>
          <izz>0.000001</izz>
        </inertia>
        <pose>0 0.3 0 0.00 0 0.0</pose>
      </inertial>
    </link>
    <link name="right_elevon">
      <inertial>
        <mass>0.00000001</mass>
        <inertia>
          <ixx>0.000001</ixx>
          <ixy>0.0</ixy>
          <iyy>0.000001</iyy>
          <ixz>0.0</ixz>
          <iyz>0.0</iyz>
          <izz>0.000001</izz>
        </inertia>
        <pose>0 -0.3 0 0.00 0 0.0</pose>
      </inertial>
    </link>
    <link name="elevator">
      <inertial>
        <mass>0.00000001</mass>
        <inertia>
          <ixx>0.000001</ixx>
          <ixy>0.0</ixy>
          <iyy>0.000001</iyy>
          <ixz>0.0</ixz>
          <iyz>0.0</iyz>
          <izz>0.000001</izz>
        </inertia>
        <pose> -0.5 0 0 0.00 0 0.0</pose>
      </inertial>
    </link>
    <link name="rudder">
      <inertial>
        <mass>0.00000001</mass>
        <inertia>
          <ixx>0.000001</ixx>
          <ixy>0.0</ixy>
          <iyy>0.000001</iyy>
          <ixz>0.0</ixz>
          <iyz>0.0</iyz>
          <izz>0.000001</izz>
        </inertia>
        <pose>-0.5 0 0.05 0 0 0 </pose>
      </inertial>
    </link>
    <joint name='left_elevon_joint' type='revolute'>
      <parent>base_link</parent>
      <child>left_elevon</child>
      <pose>0 0.3 0 0.00 0 0.0</pose>
      <axis>
        <xyz>0 1 0</xyz>
        <limit>
          <!-- -30/+30 deg. -->
          <lower>-0.53</lower>
          <upper>0.53</upper>
        </limit>
        <dynamics>
          <damping>1.000</damping>
        </dynamics>
      </axis>
      <physics>
        <ode>
          <implicit_spring_damper>1</implicit_spring_damper>
        </ode>
      </physics>
    </joint>
    <joint name='right_elevon_joint' type='revolute'>
      <parent>base_link</parent>
      <child>right_elevon</child>
      <pose>0 -0.3 0 0.00 0 0.0</pose>
      <axis>
        <xyz>0 1 0</xyz>
        <limit>
          <!-- -30/+30 deg. -->
          <lower>-0.53</lower>
          <upper>0.53</upper>
        </limit>
        <dynamics>
          <damping>1.000</damping>
        </dynamics>
      </axis>
      <physics>
        <ode>
          <implicit_spring_damper>1</implicit_spring_damper>
        </ode>
      </physics>
    </joint>
    <joint name='elevator_joint' type='revolute'>
      <parent>base_link</parent>
      <child>elevator</child>
      <pose> -0.5 0 0 0 0 0</pose>
      <axis>
        <xyz>0 1 0</xyz>
        <limit>
          <!-- -30/+30 deg. -->
          <lower>-0.53</lower>
          <upper>0.53</upper>
        </limit>
        <dynamics>
          <damping>1.000</damping>
        </dynamics>
      </axis>
      <physics>
        <ode>
          <implicit_spring_damper>1</implicit_spring_damper>
        </ode>
      </physics>
    </joint>
    <joint name='rudder_joint' type='revolute'>
      <parent>base_link</parent>
      <child>rudder</child>
      <pose>-0.5 0 0.05 0.00 0 0.0</pose>
      <axis>
        <xyz>1 0 0</xyz>
        <limit>
          <!-- -30/+30 deg. -->
          <lower>-0.01</lower>
          <upper>0.01</upper>
        </limit>
        <dynamics>
          <damping>1.000</damping>
        </dynamics>
      </axis>
      <physics>
        <ode>
          <implicit_spring_damper>1</implicit_spring_damper>
        </ode>
      </physics>
    </joint>
    <plugin name="left_wing" filename="libLiftDragPlugin.so">
      <a0>0.05984281113</a0>
      <cla>4.752798721</cla>
      <cda>0.6417112299</cda>
      <cma>-1.8</cma>
      <alpha_stall>0.3391428111</alpha_stall>
      <cla_stall>-3.85</cla_stall>
      <cda_stall>-0.9233984055</cda_stall>
      <cma_stall>0</cma_stall>
      <cp>-0.05 0.3 0.05</cp>
      <area>0.12</area>
      <air_density>1.2041</air_density>
      <forward>1 0 0</forward>
      <upward>0 0 1</upward>
      <link_name>base_link</link_name>
      <control_joint_name>
        left_elevon_joint
      </control_joint_name>
      <control_joint_rad_to_cl>-0.5</control_joint_rad_to_cl>
    </plugin>
    <plugin name="right_wing" filename="libLiftDragPlugin.so">
      <a0>0.05984281113</a0>
      <cla>4.752798721</cla>
      <cda>0.6417112299</cda>
      <cma>-1.8</cma>
      <alpha_stall>0.3391428111</alpha_stall>
      <cla_stall>-3.85</cla_stall>
      <cda_stall>-0.9233984055</cda_stall>
      <cma_stall>0</cma_stall>
      <cp>-0.05 -0.3 0.05</cp>
      <area>0.12</area>
      <air_density>1.2041</air_density>
      <forward>1 0 0</forward>
      <upward>0 0 1</upward>
      <link_name>base_link</link_name>
      <control_joint_name>
        right_elevon_joint
      </control_joint_name>
      <control_joint_rad_to_cl>-0.5</control_joint_rad_to_cl>
    </plugin>
    <plugin name="elevator" filename="libLiftDragPlugin.so">
      <a0>-0.2</a0>
      <cla>4.752798721</cla>
      <cda>0.6417112299</cda>
      <cma>-1.8</cma>
      <alpha_stall>0.3391428111</alpha_stall>
      <cla_stall>-3.85</cla_stall>
      <cda_stall>-0.9233984055</cda_stall>
      <cma_stall>0</cma_stall>
      <cp>-0.5 0 0</cp>
      <area>0.01</area>
      <air_density>1.2041</air_density>
      <forward>1 0 0</forward>
      <upward>0 0 1</upward>
      <link_name>base_link</link_name>
      <control_joint_name>
        elevator_joint
      </control_joint_name>
      <control_joint_rad_to_cl>-4.0</control_joint_rad_to_cl>
    </plugin>
    <plugin name="rudder" filename="libLiftDragPlugin.so">
      <a0>0.0</a0>
      <cla>4.752798721</cla>
      <cda>0.6417112299</cda>
      <cma>-1.8</cma>
      <alpha_stall>0.3391428111</alpha_stall>
      <cla_stall>-3.85</cla_stall>
      <cda_stall>-0.9233984055</cda_stall>
      <cma_stall>0</cma_stall>
      <cp>-0.5 0 0.05</cp>
      <area>0.02</area>
      <air_density>1.2041</air_density>
      <forward>1 0 0</forward>
      <upward>0 1 0</upward>
      <link_name>base_link</link_name>
    </plugin>
    <plugin name='puller' filename='librotors_gazebo_motor_model.so'>
      <robotNamespace></robotNamespace>
      <jointName>rotor_puller_joint</jointName>
      <linkName>rotor_puller</linkName>
      <turningDirection>cw</turningDirection>
      <timeConstantUp>0.0125</timeConstantUp>
      <timeConstantDown>0.025</timeConstantDown>
      <maxRotVelocity>3100</maxRotVelocity>
      <motorConstant>8.54858e-06</motorConstant>
      <momentConstant>0.01</momentConstant>
      <commandSubTopic>/gazebo/command/motor_speed</commandSubTopic>
      <motorNumber>4</motorNumber>
      <rotorDragCoefficient>8.06428e-05</rotorDragCoefficient>
      <rollingMomentCoefficient>1e-06</rollingMomentCoefficient>
      <motorSpeedPubTopic>/motor_speed/4</motorSpeedPubTopic>
      <rotorVelocitySlowdownSim>10</rotorVelocitySlowdownSim>
    </plugin>
    <plugin name='rotors_gazebo_imu_plugin' filename='librotors_gazebo_imu_plugin.so'>
      <robotNamespace></robotNamespace>
      <linkName>plane/imu_link</linkName>
      <imuTopic>/imu</imuTopic>
      <gyroscopeNoiseDensity>0.0003394</gyroscopeNoiseDensity>
      <gyroscopeRandomWalk>3.8785e-05</gyroscopeRandomWalk>
      <gyroscopeBiasCorrelationTime>1000.0</gyroscopeBiasCorrelationTime>
      <gyroscopeTurnOnBiasSigma>0.0087</gyroscopeTurnOnBiasSigma>
      <accelerometerNoiseDensity>0.004</accelerometerNoiseDensity>
      <accelerometerRandomWalk>0.006</accelerometerRandomWalk>
      <accelerometerBiasCorrelationTime>300.0</accelerometerBiasCorrelationTime>
      <accelerometerTurnOnBiasSigma>0.196</accelerometerTurnOnBiasSigma>
    </plugin>
    <plugin name='wind_plugin' filename='librotors_gazebo_wind_plugin.so'>
      <frameId>base_link</frameId>
      <linkName>base_link</linkName>
      <robotNamespace/>
      <xyzOffset>1 0 0</xyzOffset>
      <windDirection>0 1 0</windDirection>
      <windForceMean>0.7</windForceMean>
      <windGustDirection>0 0 0</windGustDirection>
      <windGustDuration>0</windGustDuration>
      <windGustStart>0</windGustStart>
      <windGustForceMean>0</windGustForceMean>
    </plugin>
    <plugin name='mavlink_interface' filename='librotors_gazebo_mavlink_interface.so'>
      <robotNamespace></robotNamespace>
      <imuSubTopic>/imu</imuSubTopic>
      <motorSpeedCommandPubTopic>/gazebo/command/motor_speed</motorSpeedCommandPubTopic>
      <control_channels>
        <channel name="rotor4">
          <input_index>4</input_index>
          <input_offset>0</input_offset>
          <input_scaling>3000</input_scaling>
          <zero_position_disarmed>0</zero_position_disarmed>
          <zero_position_armed>0</zero_position_armed>
          <joint_control_type>velocity</joint_control_type>
          <joint_name>rotor_puller_joint</joint_name>
        </channel>
        <channel name="left_elevon">
          <input_index>5</input_index>
          <input_offset>0</input_offset>
          <input_scaling>1</input_scaling>
          <zero_position_disarmed>0</zero_position_disarmed>
          <zero_position_armed>0</zero_position_armed>
          <joint_control_type>position_kinematic</joint_control_type>
          <joint_name>left_elevon_joint</joint_name>
        </channel>
        <channel name="right_elevon">
          <input_index>6</input_index>
          <input_offset>0</input_offset>
          <input_scaling>1</input_scaling>
          <zero_position_disarmed>0</zero_position_disarmed>
          <zero_position_armed>0</zero_position_armed>
          <joint_control_type>position_kinematic</joint_control_type>
          <joint_name>right_elevon_joint</joint_name>
        </channel>
        <channel name="elevator">
          <input_index>7</input_index>
          <input_offset>0</input_offset>
          <input_scaling>1</input_scaling>
          <zero_position_disarmed>0</zero_position_disarmed>
          <zero_position_armed>0</zero_position_armed>
          <joint_control_type>position_kinematic</joint_control_type>
          <joint_name>elevator_joint</joint_name>
        </channel>
      </control_channels>
      <left_elevon_joint>
        left_elevon_joint
      </left_elevon_joint>
      <right_elevon_joint>
        right_elevon_joint
      </right_elevon_joint>
      <elevator_joint>
        elevator_joint
      </elevator_joint>
    </plugin>
    <static>0</static>
  </model>
</sdf>
